Workbook

Sheet Como Usar
B2: Agendador de Revisões
B3: Monte seu calendário de estudos com revisões espaçadas automáticas — visões Mês, Semana e Tabela, como no calendário do app.
B6: COMO USAR — 4 PASSOS
C7: 1. Temas | D7: Para cada aula, digite o Tema, a Grande Área e a Data da aula (células amarelas). As datas da aula e das 5 revisões aparecem sozinhas.
C8: 2. Avulsos | D8: Lance simulados, blocos de questões e compromissos com data fixa (ex.: simulado UFCSPA 2026).
C9: 3. Calendário | D9: Escolha Mês e Ano no topo. Cada dia mostra até 6 itens com a cor da categoria; se houver mais, aparece “+N mais” (veja tudo em Semana ou Tabela). O dia de hoje fica destacado em verde.
C10: 4. Marcar feito | D10: Ao concluir uma etapa, escolha ✓ (ou digite x) na coluna Feito daquela etapa em Temas/Avulsos. No calendário o item fica riscado com ✓.
B12: PERSONALIZAR (aba Config)
C13: Intervalos | D13: Padrão: aula (0) e revisões com 1, 7, 15, 30 e 60 dias. Mude os números e o calendário inteiro se reorganiza.
C14: Categoria da etapa | D14: Define a cor no calendário: Teórica, Revisão, Prática (questões), Simulado ou Outro.
C15: Ativa? | D15: “Não” desliga a etapa — ela some do calendário, da tabela e do painel.
C16: Dia de descanso | D16: Revisões que cairiam nesse dia da semana vão para o dia seguinte.
C17: Mostrar sigla | D17: Exibe T, R1…R5 antes do nome do tema (ajuda a distinguir as revisões).
C18: Grandes áreas | D18: Edite a lista (até 8). Ela alimenta a lista suspensa e o Painel.
B20: REMARCAR UMA REVISÃO
C21: Data manual | D21: Na aba Temas, digite a nova data por cima da data calculada. Para voltar ao automático, copie a mesma coluna de outra linha (Ctrl+C / Ctrl+V).
B23: LEGENDA DE CORES
C24: Teórica | D24: Aula teórica (1º contato com o tema)
C25: Revisão | D25: Revisão de resumo / flashcards
C26: Prática | D26: Bloco de questões do tema
C27: Simulado | D27: Prova / simulado
C28: Outro | D28: Qualquer outro compromisso
C29: ✓ T · Cardiopediatria | D29: Riscado com ✓ = etapa concluída
C30: Célula amarela | D30: Você preenche. Células brancas são calculadas — não digite nelas (exceto para remarcar uma data).
B32: ABAS
C33: Calendário | D33: Visão do mês (como “Mês” no app). Links no topo levam às outras visões.
C34: Semana | D34: Visão semanal com até 15 itens por dia.
C35: Tabela | D35: Todos os eventos em ordem de data, com filtros (como “Tabela” no app).
C36: Painel | D36: % concluído, atrasadas, o que fazer hoje e a carga dos próximos 14 dias.
C37: Temas / Avulsos | D37: Onde você digita.
C38: Config | D38: Intervalos, categorias, áreas e preferências.
C39: Base | D39: Motor de cálculo. Não edite nem ordene.
B41: LIMITES E CUIDADOS
C42: Capacidade | D42: 300 temas e 200 eventos avulsos.
C43: Estrutura | D43: Não insira nem exclua colunas. Para tirar um tema, apague o conteúdo da linha (Tema, Área, Data e os ✓).
C44: Ordenar | D44: Para ver em outra ordem, use os filtros da aba Tabela — não ordene a aba Base.
B46: DADOS DE EXEMPLO
C47: Este arquivo | D47: Já vem com as aulas teóricas que aparecem no print (27/09 a 27/10/2026) e o simulado UFCSPA 2026, para você ver o calendário funcionando. Para começar do zero, use Agendador_de_Revisoes_em_branco.xlsx.
C48: Itens do print | D48: Os itens azuis do print que vêm de aulas anteriores a setembro: cadastre o tema com a data da aula original e as revisões entram sozinhas.

Sheet Temas
A1: Temas — cronograma de aulas
A2: Preencha as colunas amarelas: Tema, Grande Área e Data da aula. As datas das revisões são calculadas pela aba Config. Ao concluir, escolha ✓ (ou digite x) na coluna Feito da etapa.
A3: Para remarcar uma revisão, digite a nova data por cima da data calculada.
E4: =Config!$C$6&" · +"&Config!$F$6&"d" -> Aula teórica · +0d | G4: =Config!$C$7&" · +"&Config!$F$7&"d" -> 1ª Revisão · +1d | I4: =Config!$C$8&" · +"&Config!$F$8&"d" -> 2ª Revisão · +7d | K4: =Config!$C$9&" · +"&Config!$F$9&"d" -> 3ª Revisão · +15d | M4: =Config!$C$10&" · +"&Config!$F$10&"d" -> 4ª Revisão · +30d | O4: =Config!$C$11&" · +"&Config!$F$11&"d" -> 5ª Revisão · +60d
A5: Nº | B5: Tema | C5: Grande Área | D5: Data da aula | E5: Data | F5: Feito | G5: Data | H5: Feito | I5: Data | J5: Feito | K5: Data | L5: Feito | M5: Data | N5: Feito | O5: Data | P5: Feito | Q5: Progresso | R5: Próxima etapa | S5: Situação | T5: aux
A6: 1 | B6: Cardiopediatria | C6: Pediatria | D6: 46292 | E6: =IF(OR(NOT(ISNUMBER($D6)),Config!$G$6<>"Sim"),"",$D6+Config!$F$6+IF(AND(Config!$F$6>0,WEEKDAY($D6+Config!$F$6)=Config!$E$24),1,0)) -> 46292 | F6: ✓ | G6: =IF(OR(NOT(ISNUMBER($D6)),Config!$G$7<>"Sim"),"",$D6+Config!$F$7+IF(AND(Config!$F$7>0,WEEKDAY($D6+Config!$F$7)=Config!$E$24),1,0)) -> 46293 | H6: ✓ | I6: =IF(OR(NOT(ISNUMBER($D6)),Config!$G$8<>"Sim"),"",$D6+Config!$F$8+IF(AND(Config!$F$8>0,WEEKDAY($D6+Config!$F$8)=Config!$E$24),1,0)) -> 46299 | K6: =IF(OR(NOT(ISNUMBER($D6)),Config!$G$9<>"Sim"),"",$D6+Config!$F$9+IF(AND(Config!$F$9>0,WEEKDAY($D6+Config!$F$9)=Config!$E$24),1,0)) -> 46307 | M6: =IF(OR(NOT(ISNUMBER($D6)),Config!$G$10<>"Sim"),"",$D6+Config!$F$10+IF(AND(Config!$F$10>0,WEEKDAY($D6+Config!$F$10)=Config!$E$24),1,0)) -> 46322 | O6: =IF(OR(NOT(ISNUMBER($D6)),Config!$G$11<>"Sim"),"",$D6+Config!$F$11+IF(AND(Config!$F$11>0,WEEKDAY($D6+Config!$F$11)=Config!$E$24),1,0)) -> 46352 | Q6: =IF(COUNT(E6,G6,I6,K6,M6,O6)=0,"",((E6<>"")*(F6<>"")+(G6<>"")*(H6<>"")+(I6<>"")*(J6<>"")+(K6<>"")*(L6<>"")+(M6<>"")*(N6<>"")+(O6<>"")*(P6<>""))/COUNT(E6,G6,I6,K6,M6,O6)) -> 0.33333333 | R6: =IF(T6="","",IF(T6=99999,"",T6)) -> 46299 | S6: =IF(T6="","",IF(T6=99999,"Concluído",IF(T6<TODAY(),"Atrasado",IF(T6=TODAY(),"Hoje","Em dia")))) -> Atrasado | T6: =IF(COUNT(E6,G6,I6,K6,M6,O6)=0,"",MIN(IF(AND(E6<>"",F6=""),E6,99999),IF(AND(G6<>"",H6=""),G6,99999),IF(AND(I6<>"",J6=""),I6,99999),IF(AND(K6<>"",L6=""),K6,99999),IF(AND(M6<>"",N6=""),M6,99999),IF(AND(O6<>"",P6=""),O6,99999))) -> 46299
A7: 2 | B7: Nefrologia Pediátrica / ITU | C7: Pediatria | D7: 46292 | E7: =IF(OR(NOT(ISNUMBER($D7)),Config!$G$6<>"Sim"),"",$D7+Config!$F$6+IF(AND(Config!$F$6>0,WEEKDAY($D7+Config!$F$6)=Config!$E$24),1,0)) -> 46292 | F7: ✓ | G7: =IF(OR(NOT(ISNUMBER($D7)),Config!$G$7<>"Sim"),"",$D7+Config!$F$7+IF(AND(Config!$F$7>0,WEEKDAY($D7+Config!$F$7)=Config!$E$24),1,0)) -> 46293 | H7: ✓ | I7: =IF(OR(NOT(ISNUMBER($D7)),Config!$G$8<>"Sim"),"",$D7+Config!$F$8+IF(AND(Config!$F$8>0,WEEKDAY($D7+Config!$F$8)=Config!$E$24),1,0)) -> 46299 | K7: =IF(OR(NOT(ISNUMBER($D7)),Config!$G$9<>"Sim"),"",$D7+Config!$F$9+IF(AND(Config!$F$9>0,WEEKDAY($D7+Config!$F$9)=Config!$E$24),1,0)) -> 46307 | M7: =IF(OR(NOT(ISNUMBER($D7)),Config!$G$10<>"Sim"),"",$D7+Config!$F$10+IF(AND(Config!$F$10>0,WEEKDAY($D7+Config!$F$10)=Config!$E$24),1,0)) -> 46322 | O7: =IF(OR(NOT(ISNUMBER($D7)),Config!$G$11<>"Sim"),"",$D7+Config!$F$11+IF(AND(Config!$F$11>0,WEEKDAY($D7+Config!$F$11)=Config!$E$24),1,0)) -> 46352 | Q7: =IF(COUNT(E7,G7,I7,K7,M7,O7)=0,"",((E7<>"")*(F7<>"")+(G7<>"")*(H7<>"")+(I7<>"")*(J7<>"")+(K7<>"")*(L7<>"")+(M7<>"")*(N7<>"")+(O7<>"")*(P7<>""))/COUNT(E7,G7,I7,K7,M7,O7)) -> 0.33333333 | R7: =IF(T7="","",IF(T7=99999,"",T7)) -> 46299 | S7: =IF(T7="","",IF(T7=99999,"Concluído",IF(T7<TODAY(),"Atrasado",IF(T7=TODAY(),"Hoje","Em dia")))) -> Atrasado | T7: =IF(COUNT(E7,G7,I7,K7,M7,O7)=0,"",MIN(IF(AND(E7<>"",F7=""),E7,99999),IF(AND(G7<>"",H7=""),G7,99999),IF(AND(I7<>"",J7=""),I7,99999),IF(AND(K7<>"",L7=""),K7,99999),IF(AND(M7<>"",N7=""),M7,99999),IF(AND(O7<>"",P7=""),O7,99999))) -> 46299
A8: 3 | B8: Asma e DPOC | C8: Clínica Médica | D8: 46292 | E8: =IF(OR(NOT(ISNUMBER($D8)),Config!$G$6<>"Sim"),"",$D8+Config!$F$6+IF(AND(Config!$F$6>0,WEEKDAY($D8+Config!$F$6)=Config!$E$24),1,0)) -> 46292 | F8: ✓ | G8: =IF(OR(NOT(ISNUMBER($D8)),Config!$G$7<>"Sim"),"",$D8+Config!$F$7+IF(AND(Config!$F$7>0,WEEKDAY($D8+Config!$F$7)=Config!$E$24),1,0)) -> 46293 | H8: ✓ | I8: =IF(OR(NOT(ISNUMBER($D8)),Config!$G$8<>"Sim"),"",$D8+Config!$F$8+IF(AND(Config!$F$8>0,WEEKDAY($D8+Config!$F$8)=Config!$E$24),1,0)) -> 46299 | K8: =IF(OR(NOT(ISNUMBER($D8)),Config!$G$9<>"Sim"),"",$D8+Config!$F$9+IF(AND(Config!$F$9>0,WEEKDAY($D8+Config!$F$9)=Config!$E$24),1,0)) -> 46307 | M8: =IF(OR(NOT(ISNUMBER($D8)),Config!$G$10<>"Sim"),"",$D8+Config!$F$10+IF(AND(Config!$F$10>0,WEEKDAY($D8+Config!$F$10)=Config!$E$24),1,0)) -> 46322 | O8: =IF(OR(NOT(ISNUMBER($D8)),Config!$G$11<>"Sim"),"",$D8+Config!$F$11+IF(AND(Config!$F$11>0,WEEKDAY($D8+Config!$F$11)=Config!$E$24),1,0)) -> 46352 | Q8: =IF(COUNT(E8,G8,I8,K8,M8,O8)=0,"",((E8<>"")*(F8<>"")+(G8<>"")*(H8<>"")+(I8<>"")*(J8<>"")+(K8<>"")*(L8<>"")+(M8<>"")*(N8<>"")+(O8<>"")*(P8<>""))/COUNT(E8,G8,I8,K8,M8,O8)) -> 0.33333333 | R8: =IF(T8="","",IF(T8=99999,"",T8)) -> 46299 | S8: =IF(T8="","",IF(T8=99999,"Concluído",IF(T8<TODAY(),"Atrasado",IF(T8=TODAY(),"Hoje","Em dia")))) -> Atrasado | T8: =IF(COUNT(E8,G8,I8,K8,M8,O8)=0,"",MIN(IF(AND(E8<>"",F8=""),E8,99999),IF(AND(G8<>"",H8=""),G8,99999),IF(AND(I8<>"",J8=""),I8,99999),IF(AND(K8<>"",L8=""),K8,99999),IF(AND(M8<>"",N8=""),M8,99999),IF(AND(O8<>"",P8=""),O8,99999))) -> 46299
A9: 4 | B9: Doenças da Tireoide | C9: Clínica Médica | D9: 46293 | E9: =IF(OR(NOT(ISNUMBER($D9)),Config!$G$6<>"Sim"),"",$D9+Config!$F$6+IF(AND(Config!$F$6>0,WEEKDAY($D9+Config!$F$6)=Config!$E$24),1,0)) -> 46293 | F9: ✓ | G9: =IF(OR(NOT(ISNUMBER($D9)),Config!$G$7<>"Sim"),"",$D9+Config!$F$7+IF(AND(Config!$F$7>0,WEEKDAY($D9+Config!$F$7)=Config!$E$24),1,0)) -> 46294 | H9: ✓ | I9: =IF(OR(NOT(ISNUMBER($D9)),Config!$G$8<>"Sim"),"",$D9+Config!$F$8+IF(AND(Config!$F$8>0,WEEKDAY($D9+Config!$F$8)=Config!$E$24),1,0)) -> 46300 | K9: =IF(OR(NOT(ISNUMBER($D9)),Config!$G$9<>"Sim"),"",$D9+Config!$F$9+IF(AND(Config!$F$9>0,WEEKDAY($D9+Config!$F$9)=Config!$E$24),1,0)) -> 46308 | M9: =IF(OR(NOT(ISNUMBER($D9)),Config!$G$10<>"Sim"),"",$D9+Config!$F$10+IF(AND(Config!$F$10>0,WEEKDAY($D9+Config!$F$10)=Config!$E$24),1,0)) -> 46323 | O9: =IF(OR(NOT(ISNUMBER($D9)),Config!$G$11<>"Sim"),"",$D9+Config!$F$11+IF(AND(Config!$F$11>0,WEEKDAY($D9+Config!$F$11)=Config!$E$24),1,0)) -> 46353 | Q9: =IF(COUNT(E9,G9,I9,K9,M9,O9)=0,"",((E9<>"")*(F9<>"")+(G9<>"")*(H9<>"")+(I9<>"")*(J9<>"")+(K9<>"")*(L9<>"")+(M9<>"")*(N9<>"")+(O9<>"")*(P9<>""))/COUNT(E9,G9,I9,K9,M9,O9)) -> 0.33333333 | R9: =IF(T9="","",IF(T9=99999,"",T9)) -> 46300 | S9: =IF(T9="","",IF(T9=99999,"Concluído",IF(T9<TODAY(),"Atrasado",IF(T9=TODAY(),"Hoje","Em dia")))) -> Atrasado | T9: =IF(COUNT(E9,G9,I9,K9,M9,O9)=0,"",MIN(IF(AND(E9<>"",F9=""),E9,99999),IF(AND(G9<>"",H9=""),G9,99999),IF(AND(I9<>"",J9=""),I9,99999),IF(AND(K9<>"",L9=""),K9,99999),IF(AND(M9<>"",N9=""),M9,99999),IF(AND(O9<>"",P9=""),O9,99999))) -> 46300
A10: 5 | B10: Valvopatias | C10: Clínica Médica | D10: 46293 | E10: =IF(OR(NOT(ISNUMBER($D10)),Config!$G$6<>"Sim"),"",$D10+Config!$F$6+IF(AND(Config!$F$6>0,WEEKDAY($D10+Config!$F$6)=Config!$E$24),1,0)) -> 46293 | G10: =IF(OR(NOT(ISNUMBER($D10)),Config!$G$7<>"Sim"),"",$D10+Config!$F$7+IF(AND(Config!$F$7>0,WEEKDAY($D10+Config!$F$7)=Config!$E$24),1,0)) -> 46294 | I10: =IF(OR(NOT(ISNUMBER($D10)),Config!$G$8<>"Sim"),"",$D10+Config!$F$8+IF(AND(Config!$F$8>0,WEEKDAY($D10+Config!$F$8)=Config!$E$24),1,0)) -> 46300 | K10: =IF(OR(NOT(ISNUMBER($D10)),Config!$G$9<>"Sim"),"",$D10+Config!$F$9+IF(AND(Config!$F$9>0,WEEKDAY($D10+Config!$F$9)=Config!$E$24),1,0)) -> 46308 | M10: =IF(OR(NOT(ISNUMBER($D10)),Config!$G$10<>"Sim"),"",$D10+Config!$F$10+IF(AND(Config!$F$10>0,WEEKDAY($D10+Config!$F$10)=Config!$E$24),1,0)) -> 46323 | O10: =IF(OR(NOT(ISNUMBER($D10)),Config!$G$11<>"Sim"),"",$D10+Config!$F$11+IF(AND(Config!$F$11>0,WEEKDAY($D10+Config!$F$11)=Config!$E$24),1,0)) -> 46353 | Q10: =IF(COUNT(E10,G10,I10,K10,M10,O10)=0,"",((E10<>"")*(F10<>"")+(G10<>"")*(H10<>"")+(I10<>"")*(J10<>"")+(K10<>"")*(L10<>"")+(M10<>"")*(N10<>"")+(O10<>"")*(P10<>""))/COUNT(E10,G10,I10,K10,M10,O10)) -> 0 | R10: =IF(T10="","",IF(T10=99999,"",T10)) -> 46293 | S10: =IF(T10="","",IF(T10=99999,"Concluído",IF(T10<TODAY(),"Atrasado",IF(T10=TODAY(),"Hoje","Em dia")))) -> Atrasado | T10: =IF(COUNT(E10,G10,I10,K10,M10,O10)=0,"",MIN(IF(AND(E10<>"",F10=""),E10,99999),IF(AND(G10<>"",H10=""),G10,99999),IF(AND(I10<>"",J10=""),I10,99999),IF(AND(K10<>"",L10=""),K10,99999),IF(AND(M10<>"",N10=""),M10,99999),IF(AND(O10<>"",P10=""),O10,99999))) -> 46293
A11: 6 | B11: Demência e Parkinson | C11: Clínica Médica | D11: 46293 | E11: =IF(OR(NOT(ISNUMBER($D11)),Config!$G$6<>"Sim"),"",$D11+Config!$F$6+IF(AND(Config!$F$6>0,WEEKDAY($D11+Config!$F$6)=Config!$E$24),1,0)) -> 46293 | G11: =IF(OR(NOT(ISNUMBER($D11)),Config!$G$7<>"Sim"),"",$D11+Config!$F$7+IF(AND(Config!$F$7>0,WEEKDAY($D11+Config!$F$7)=Config!$E$24),1,0)) -> 46294 | I11: =IF(OR(NOT(ISNUMBER($D11)),Config!$G$8<>"Sim"),"",$D11+Config!$F$8+IF(AND(Config!$F$8>0,WEEKDAY($D11+Config!$F$8)=Config!$E$24),1,0)) -> 46300 | K11: =IF(OR(NOT(ISNUMBER($D11)),Config!$G$9<>"Sim"),"",$D11+Config!$F$9+IF(AND(Config!$F$9>0,WEEKDAY($D11+Config!$F$9)=Config!$E$24),1,0)) -> 46308 | M11: =IF(OR(NOT(ISNUMBER($D11)),Config!$G$10<>"Sim"),"",$D11+Config!$F$10+IF(AND(Config!$F$10>0,WEEKDAY($D11+Config!$F$10)=Config!$E$24),1,0)) -> 46323 | O11: =IF(OR(NOT(ISNUMBER($D11)),Config!$G$11<>"Sim"),"",$D11+Config!$F$11+IF(AND(Config!$F$11>0,WEEKDAY($D11+Config!$F$11)=Config!$E$24),1,0)) -> 46353 | Q11: =IF(COUNT(E11,G11,I11,K11,M11,O11)=0,"",((E11<>"")*(F11<>"")+(G11<>"")*(H11<>"")+(I11<>"")*(J11<>"")+(K11<>"")*(L11<>"")+(M11<>"")*(N11<>"")+(O11<>"")*(P11<>""))/COUNT(E11,G11,I11,K11,M11,O11)) -> 0 | R11: =IF(T11="","",IF(T11=99999,"",T11)) -> 46293 | S11: =IF(T11="","",IF(T11=99999,"Concluído",IF(T11<TODAY(),"Atrasado",IF(T11=TODAY(),"Hoje","Em dia")))) -> Atrasado | T11: =IF(COUNT(E11,G11,I11,K11,M11,O11)=0,"",MIN(IF(AND(E11<>"",F11=""),E11,99999),IF(AND(G11<>"",H11=""),G11,99999),IF(AND(I11<>"",J11=""),I11,99999),IF(AND(K11<>"",L11=""),K11,99999),IF(AND(M11<>"",N11=""),M11,99999),IF(AND(O11<>"",P11=""),O11,99999))) -> 46293
A12: 7 | B12: ATB | C12: Clínica Médica | D12: 46297 | E12: =IF(OR(NOT(ISNUMBER($D12)),Config!$G$6<>"Sim"),"",$D12+Config!$F$6+IF(AND(Config!$F$6>0,WEEKDAY($D12+Config!$F$6)=Config!$E$24),1,0)) -> 46297 | F12: ✓ | G12: =IF(OR(NOT(ISNUMBER($D12)),Config!$G$7<>"Sim"),"",$D12+Config!$F$7+IF(AND(Config!$F$7>0,WEEKDAY($D12+Config!$F$7)=Config!$E$24),1,0)) -> 46298 | I12: =IF(OR(NOT(ISNUMBER($D12)),Config!$G$8<>"Sim"),"",$D12+Config!$F$8+IF(AND(Config!$F$8>0,WEEKDAY($D12+Config!$F$8)=Config!$E$24),1,0)) -> 46304 | K12: =IF(OR(NOT(ISNUMBER($D12)),Config!$G$9<>"Sim"),"",$D12+Config!$F$9+IF(AND(Config!$F$9>0,WEEKDAY($D12+Config!$F$9)=Config!$E$24),1,0)) -> 46312 | M12: =IF(OR(NOT(ISNUMBER($D12)),Config!$G$10<>"Sim"),"",$D12+Config!$F$10+IF(AND(Config!$F$10>0,WEEKDAY($D12+Config!$F$10)=Config!$E$24),1,0)) -> 46327 | O12: =IF(OR(NOT(ISNUMBER($D12)),Config!$G$11<>"Sim"),"",$D12+Config!$F$11+IF(AND(Config!$F$11>0,WEEKDAY($D12+Config!$F$11)=Config!$E$24),1,0)) -> 46357 | Q12: =IF(COUNT(E12,G12,I12,K12,M12,O12)=0,"",((E12<>"")*(F12<>"")+(G12<>"")*(H12<>"")+(I12<>"")*(J12<>"")+(K12<>"")*(L12<>"")+(M12<>"")*(N12<>"")+(O12<>"")*(P12<>""))/COUNT(E12,G12,I12,K12,M12,O12)) -> 0.16666667 | R12: =IF(T12="","",IF(T12=99999,"",T12)) -> 46298 | S12: =IF(T12="","",IF(T12=99999,"Concluído",IF(T12<TODAY(),"Atrasado",IF(T12=TODAY(),"Hoje","Em dia")))) -> Atrasado | T12: =IF(COUNT(E12,G12,I12,K12,M12,O12)=0,"",MIN(IF(AND(E12<>"",F12=""),E12,99999),IF(AND(G12<>"",H12=""),G12,99999),IF(AND(I12<>"",J12=""),I12,99999),IF(AND(K12<>"",L12=""),K12,99999),IF(AND(M12<>"",N12=""),M12,99999),IF(AND(O12<>"",P12=""),O12,99999))) -> 46298
A13: 8 | B13: Transtornos Psiquiátricos I | C13: Clínica Médica | D13: 46300 | E13: =IF(OR(NOT(ISNUMBER($D13)),Config!$G$6<>"Sim"),"",$D13+Config!$F$6+IF(AND(Config!$F$6>0,WEEKDAY($D13+Config!$F$6)=Config!$E$24),1,0)) -> 46300 | G13: =IF(OR(NOT(ISNUMBER($D13)),Config!$G$7<>"Sim"),"",$D13+Config!$F$7+IF(AND(Config!$F$7>0,WEEKDAY($D13+Config!$F$7)=Config!$E$24),1,0)) -> 46301 | I13: =IF(OR(NOT(ISNUMBER($D13)),Config!$G$8<>"Sim"),"",$D13+Config!$F$8+IF(AND(Config!$F$8>0,WEEKDAY($D13+Config!$F$8)=Config!$E$24),1,0)) -> 46307 | K13: =IF(OR(NOT(ISNUMBER($D13)),Config!$G$9<>"Sim"),"",$D13+Config!$F$9+IF(AND(Config!$F$9>0,WEEKDAY($D13+Config!$F$9)=Config!$E$24),1,0)) -> 46315 | M13: =IF(OR(NOT(ISNUMBER($D13)),Config!$G$10<>"Sim"),"",$D13+Config!$F$10+IF(AND(Config!$F$10>0,WEEKDAY($D13+Config!$F$10)=Config!$E$24),1,0)) -> 46330 | O13: =IF(OR(NOT(ISNUMBER($D13)),Config!$G$11<>"Sim"),"",$D13+Config!$F$11+IF(AND(Config!$F$11>0,WEEKDAY($D13+Config!$F$11)=Config!$E$24),1,0)) -> 46360 | Q13: =IF(COUNT(E13,G13,I13,K13,M13,O13)=0,"",((E13<>"")*(F13<>"")+(G13<>"")*(H13<>"")+(I13<>"")*(J13<>"")+(K13<>"")*(L13<>"")+(M13<>"")*(N13<>"")+(O13<>"")*(P13<>""))/COUNT(E13,G13,I13,K13,M13,O13)) -> 0 | R13: =IF(T13="","",IF(T13=99999,"",T13)) -> 46300 | S13: =IF(T13="","",IF(T13=99999,"Concluído",IF(T13<TODAY(),"Atrasado",IF(T13=TODAY(),"Hoje","Em dia")))) -> Atrasado | T13: =IF(COUNT(E13,G13,I13,K13,M13,O13)=0,"",MIN(IF(AND(E13<>"",F13=""),E13,99999),IF(AND(G13<>"",H13=""),G13,99999),IF(AND(I13<>"",J13=""),I13,99999),IF(AND(K13<>"",L13=""),K13,99999),IF(AND(M13<>"",N13=""),M13,99999),IF(AND(O13<>"",P13=""),O13,99999))) -> 46300
A14: 9 | B14: Síndromes Febris — Dengue | C14: Clínica Médica | D14: 46303 | E14: =IF(OR(NOT(ISNUMBER($D14)),Config!$G$6<>"Sim"),"",$D14+Config!$F$6+IF(AND(Config!$F$6>0,WEEKDAY($D14+Config!$F$6)=Config!$E$24),1,0)) -> 46303 | F14: ✓ | G14: =IF(OR(NOT(ISNUMBER($D14)),Config!$G$7<>"Sim"),"",$D14+Config!$F$7+IF(AND(Config!$F$7>0,WEEKDAY($D14+Config!$F$7)=Config!$E$24),1,0)) -> 46304 | I14: =IF(OR(NOT(ISNUMBER($D14)),Config!$G$8<>"Sim"),"",$D14+Config!$F$8+IF(AND(Config!$F$8>0,WEEKDAY($D14+Config!$F$8)=Config!$E$24),1,0)) -> 46310 | K14: =IF(OR(NOT(ISNUMBER($D14)),Config!$G$9<>"Sim"),"",$D14+Config!$F$9+IF(AND(Config!$F$9>0,WEEKDAY($D14+Config!$F$9)=Config!$E$24),1,0)) -> 46318 | M14: =IF(OR(NOT(ISNUMBER($D14)),Config!$G$10<>"Sim"),"",$D14+Config!$F$10+IF(AND(Config!$F$10>0,WEEKDAY($D14+Config!$F$10)=Config!$E$24),1,0)) -> 46333 | O14: =IF(OR(NOT(ISNUMBER($D14)),Config!$G$11<>"Sim"),"",$D14+Config!$F$11+IF(AND(Config!$F$11>0,WEEKDAY($D14+Config!$F$11)=Config!$E$24),1,0)) -> 46363 | Q14: =IF(COUNT(E14,G14,I14,K14,M14,O14)=0,"",((E14<>"")*(F14<>"")+(G14<>"")*(H14<>"")+(I14<>"")*(J14<>"")+(K14<>"")*(L14<>"")+(M14<>"")*(N14<>"")+(O14<>"")*(P14<>""))/COUNT(E14,G14,I14,K14,M14,O14)) -> 0.16666667 | R14: =IF(T14="","",IF(T14=99999,"",T14)) -> 46304 | S14: =IF(T14="","",IF(T14=99999,"Concluído",IF(T14<TODAY(),"Atrasado",IF(T14=TODAY(),"Hoje","Em dia")))) -> Em dia | T14: =IF(COUNT(E14,G14,I14,K14,M14,O14)=0,"",MIN(IF(AND(E14<>"",F14=""),E14,99999),IF(AND(G14<>"",H14=""),G14,99999),IF(AND(I14<>"",J14=""),I14,99999),IF(AND(K14<>"",L14=""),K14,99999),IF(AND(M14<>"",N14=""),M14,99999),IF(AND(O14<>"",P14=""),O14,99999))) -> 46304
A15: 10 | B15: Endocardite Infecciosa / Meningites | C15: Clínica Médica | D15: 46306 | E15: =IF(OR(NOT(ISNUMBER($D15)),Config!$G$6<>"Sim"),"",$D15+Config!$F$6+IF(AND(Config!$F$6>0,WEEKDAY($D15+Config!$F$6)=Config!$E$24),1,0)) -> 46306 | G15: =IF(OR(NOT(ISNUMBER($D15)),Config!$G$7<>"Sim"),"",$D15+Config!$F$7+IF(AND(Config!$F$7>0,WEEKDAY($D15+Config!$F$7)=Config!$E$24),1,0)) -> 46307 | I15: =IF(OR(NOT(ISNUMBER($D15)),Config!$G$8<>"Sim"),"",$D15+Config!$F$8+IF(AND(Config!$F$8>0,WEEKDAY($D15+Config!$F$8)=Config!$E$24),1,0)) -> 46313 | K15: =IF(OR(NOT(ISNUMBER($D15)),Config!$G$9<>"Sim"),"",$D15+Config!$F$9+IF(AND(Config!$F$9>0,WEEKDAY($D15+Config!$F$9)=Config!$E$24),1,0)) -> 46321 | M15: =IF(OR(NOT(ISNUMBER($D15)),Config!$G$10<>"Sim"),"",$D15+Config!$F$10+IF(AND(Config!$F$10>0,WEEKDAY($D15+Config!$F$10)=Config!$E$24),1,0)) -> 46336 | O15: =IF(OR(NOT(ISNUMBER($D15)),Config!$G$11<>"Sim"),"",$D15+Config!$F$11+IF(AND(Config!$F$11>0,WEEKDAY($D15+Config!$F$11)=Config!$E$24),1,0)) -> 46366 | Q15: =IF(COUNT(E15,G15,I15,K15,M15,O15)=0,"",((E15<>"")*(F15<>"")+(G15<>"")*(H15<>"")+(I15<>"")*(J15<>"")+(K15<>"")*(L15<>"")+(M15<>"")*(N15<>"")+(O15<>"")*(P15<>""))/COUNT(E15,G15,I15,K15,M15,O15)) -> 0 | R15: =IF(T15="","",IF(T15=99999,"",T15)) -> 46306 | S15: =IF(T15="","",IF(T15=99999,"Concluído",IF(T15<TODAY(),"Atrasado",IF(T15=TODAY(),"Hoje","Em dia")))) -> Em dia | T15: =IF(COUNT(E15,G15,I15,K15,M15,O15)=0,"",MIN(IF(AND(E15<>"",F15=""),E15,99999),IF(AND(G15<>"",H15=""),G15,99999),IF(AND(I15<>"",J15=""),I15,99999),IF(AND(K15<>"",L15=""),K15,99999),IF(AND(M15<>"",N15=""),M15,99999),IF(AND(O15<>"",P15=""),O15,99999))) -> 46306
A16: 11 | B16: Especialidade Cirúrgica I | C16: Cirurgia | D16: 46307 | E16: =IF(OR(NOT(ISNUMBER($D16)),Config!$G$6<>"Sim"),"",$D16+Config!$F$6+IF(AND(Config!$F$6>0,WEEKDAY($D16+Config!$F$6)=Config!$E$24),1,0)) -> 46307 | G16: =IF(OR(NOT(ISNUMBER($D16)),Config!$G$7<>"Sim"),"",$D16+Config!$F$7+IF(AND(Config!$F$7>0,WEEKDAY($D16+Config!$F$7)=Config!$E$24),1,0)) -> 46308 | I16: =IF(OR(NOT(ISNUMBER($D16)),Config!$G$8<>"Sim"),"",$D16+Config!$F$8+IF(AND(Config!$F$8>0,WEEKDAY($D16+Config!$F$8)=Config!$E$24),1,0)) -> 46314 | K16: =IF(OR(NOT(ISNUMBER($D16)),Config!$G$9<>"Sim"),"",$D16+Config!$F$9+IF(AND(Config!$F$9>0,WEEKDAY($D16+Config!$F$9)=Config!$E$24),1,0)) -> 46322 | M16: =IF(OR(NOT(ISNUMBER($D16)),Config!$G$10<>"Sim"),"",$D16+Config!$F$10+IF(AND(Config!$F$10>0,WEEKDAY($D16+Config!$F$10)=Config!$E$24),1,0)) -> 46337 | O16: =IF(OR(NOT(ISNUMBER($D16)),Config!$G$11<>"Sim"),"",$D16+Config!$F$11+IF(AND(Config!$F$11>0,WEEKDAY($D16+Config!$F$11)=Config!$E$24),1,0)) -> 46367 | Q16: =IF(COUNT(E16,G16,I16,K16,M16,O16)=0,"",((E16<>"")*(F16<>"")+(G16<>"")*(H16<>"")+(I16<>"")*(J16<>"")+(K16<>"")*(L16<>"")+(M16<>"")*(N16<>"")+(O16<>"")*(P16<>""))/COUNT(E16,G16,I16,K16,M16,O16)) -> 0 | R16: =IF(T16="","",IF(T16=99999,"",T16)) -> 46307 | S16: =IF(T16="","",IF(T16=99999,"Concluído",IF(T16<TODAY(),"Atrasado",IF(T16=TODAY(),"Hoje","Em dia")))) -> Em dia | T16: =IF(COUNT(E16,G16,I16,K16,M16,O16)=0,"",MIN(IF(AND(E16<>"",F16=""),E16,99999),IF(AND(G16<>"",H16=""),G16,99999),IF(AND(I16<>"",J16=""),I16,99999),IF(AND(K16<>"",L16=""),K16,99999),IF(AND(M16<>"",N16=""),M16,99999),IF(AND(O16<>"",P16=""),O16,99999))) -> 46307
A17: 12 | B17: Especialidade Cirúrgica II | C17: Cirurgia | D17: 46307 | E17: =IF(OR(NOT(ISNUMBER($D17)),Config!$G$6<>"Sim"),"",$D17+Config!$F$6+IF(AND(Config!$F$6>0,WEEKDAY($D17+Config!$F$6)=Config!$E$24),1,0)) -> 46307 | G17: =IF(OR(NOT(ISNUMBER($D17)),Config!$G$7<>"Sim"),"",$D17+Config!$F$7+IF(AND(Config!$F$7>0,WEEKDAY($D17+Config!$F$7)=Config!$E$24),1,0)) -> 46308 | I17: =IF(OR(NOT(ISNUMBER($D17)),Config!$G$8<>"Sim"),"",$D17+Config!$F$8+IF(AND(Config!$F$8>0,WEEKDAY($D17+Config!$F$8)=Config!$E$24),1,0)) -> 46314 | K17: =IF(OR(NOT(ISNUMBER($D17)),Config!$G$9<>"Sim"),"",$D17+Config!$F$9+IF(AND(Config!$F$9>0,WEEKDAY($D17+Config!$F$9)=Config!$E$24),1,0)) -> 46322 | M17: =IF(OR(NOT(ISNUMBER($D17)),Config!$G$10<>"Sim"),"",$D17+Config!$F$10+IF(AND(Config!$F$10>0,WEEKDAY($D17+Config!$F$10)=Config!$E$24),1,0)) -> 46337 | O17: =IF(OR(NOT(ISNUMBER($D17)),Config!$G$11<>"Sim"),"",$D17+Config!$F$11+IF(AND(Config!$F$11>0,WEEKDAY($D17+Config!$F$11)=Config!$E$24),1,0)) -> 46367 | Q17: =IF(COUNT(E17,G17,I17,K17,M17,O17)=0,"",((E17<>"")*(F17<>"")+(G17<>"")*(H17<>"")+(I17<>"")*(J17<>"")+(K17<>"")*(L17<>"")+(M17<>"")*(N17<>"")+(O17<>"")*(P17<>""))/COUNT(E17,G17,I17,K17,M17,O17)) -> 0 | R17: =IF(T17="","",IF(T17=99999,"",T17)) -> 46307 | S17: =IF(T17="","",IF(T17=99999,"Concluído",IF(T17<TODAY(),"Atrasado",IF(T17=TODAY(),"Hoje","Em dia")))) -> Em dia | T17: =IF(COUNT(E17,G17,I17,K17,M17,O17)=0,"",MIN(IF(AND(E17<>"",F17=""),E17,99999),IF(AND(G17<>"",H17=""),G17,99999),IF(AND(I17<>"",J17=""),I17,99999),IF(AND(K17<>"",L17=""),K17,99999),IF(AND(M17<>"",N17=""),M17,99999),IF(AND(O17<>"",P17=""),O17,99999))) -> 46307
A18: 13 | B18: Distúrbios Hipertensivos na Gestação | C18: Ginecologia e Obstetrícia | D18: 46309 | E18: =IF(OR(NOT(ISNUMBER($D18)),Config!$G$6<>"Sim"),"",$D18+Config!$F$6+IF(AND(Config!$F$6>0,WEEKDAY($D18+Config!$F$6)=Config!$E$24),1,0)) -> 46309 | G18: =IF(OR(NOT(ISNUMBER($D18)),Config!$G$7<>"Sim"),"",$D18+Config!$F$7+IF(AND(Config!$F$7>0,WEEKDAY($D18+Config!$F$7)=Config!$E$24),1,0)) -> 46310 | I18: =IF(OR(NOT(ISNUMBER($D18)),Config!$G$8<>"Sim"),"",$D18+Config!$F$8+IF(AND(Config!$F$8>0,WEEKDAY($D18+Config!$F$8)=Config!$E$24),1,0)) -> 46316 | K18: =IF(OR(NOT(ISNUMBER($D18)),Config!$G$9<>"Sim"),"",$D18+Config!$F$9+IF(AND(Config!$F$9>0,WEEKDAY($D18+Config!$F$9)=Config!$E$24),1,0)) -> 46324 | M18: =IF(OR(NOT(ISNUMBER($D18)),Config!$G$10<>"Sim"),"",$D18+Config!$F$10+IF(AND(Config!$F$10>0,WEEKDAY($D18+Config!$F$10)=Config!$E$24),1,0)) -> 46339 | O18: =IF(OR(NOT(ISNUMBER($D18)),Config!$G$11<>"Sim"),"",$D18+Config!$F$11+IF(AND(Config!$F$11>0,WEEKDAY($D18+Config!$F$11)=Config!$E$24),1,0)) -> 46369 | Q18: =IF(COUNT(E18,G18,I18,K18,M18,O18)=0,"",((E18<>"")*(F18<>"")+(G18<>"")*(H18<>"")+(I18<>"")*(J18<>"")+(K18<>"")*(L18<>"")+(M18<>"")*(N18<>"")+(O18<>"")*(P18<>""))/COUNT(E18,G18,I18,K18,M18,O18)) -> 0 | R18: =IF(T18="","",IF(T18=99999,"",T18)) -> 46309 | S18: =IF(T18="","",IF(T18=99999,"Concluído",IF(T18<TODAY(),"Atrasado",IF(T18=TODAY(),"Hoje","Em dia")))) -> Em dia | T18: =IF(COUNT(E18,G18,I18,K18,M18,O18)=0,"",MIN(IF(AND(E18<>"",F18=""),E18,99999),IF(AND(G18<>"",H18=""),G18,99999),IF(AND(I18<>"",J18=""),I18,99999),IF(AND(K18<>"",L18=""),K18,99999),IF(AND(M18<>"",N18=""),M18,99999),IF(AND(O18<>"",P18=""),O18,99999))) -> 46309
A19: 14 | B19: Sofrimento Fetal e Vitalidade Fetal | C19: Ginecologia e Obstetrícia | D19: 46309 | E19: =IF(OR(NOT(ISNUMBER($D19)),Config!$G$6<>"Sim"),"",$D19+Config!$F$6+IF(AND(Config!$F$6>0,WEEKDAY($D19+Config!$F$6)=Config!$E$24),1,0)) -> 46309 | G19: =IF(OR(NOT(ISNUMBER($D19)),Config!$G$7<>"Sim"),"",$D19+Config!$F$7+IF(AND(Config!$F$7>0,WEEKDAY($D19+Config!$F$7)=Config!$E$24),1,0)) -> 46310 | I19: =IF(OR(NOT(ISNUMBER($D19)),Config!$G$8<>"Sim"),"",$D19+Config!$F$8+IF(AND(Config!$F$8>0,WEEKDAY($D19+Config!$F$8)=Config!$E$24),1,0)) -> 46316 | K19: =IF(OR(NOT(ISNUMBER($D19)),Config!$G$9<>"Sim"),"",$D19+Config!$F$9+IF(AND(Config!$F$9>0,WEEKDAY($D19+Config!$F$9)=Config!$E$24),1,0)) -> 46324 | M19: =IF(OR(NOT(ISNUMBER($D19)),Config!$G$10<>"Sim"),"",$D19+Config!$F$10+IF(AND(Config!$F$10>0,WEEKDAY($D19+Config!$F$10)=Config!$E$24),1,0)) -> 46339 | O19: =IF(OR(NOT(ISNUMBER($D19)),Config!$G$11<>"Sim"),"",$D19+Config!$F$11+IF(AND(Config!$F$11>0,WEEKDAY($D19+Config!$F$11)=Config!$E$24),1,0)) -> 46369 | Q19: =IF(COUNT(E19,G19,I19,K19,M19,O19)=0,"",((E19<>"")*(F19<>"")+(G19<>"")*(H19<>"")+(I19<>"")*(J19<>"")+(K19<>"")*(L19<>"")+(M19<>"")*(N19<>"")+(O19<>"")*(P19<>""))/COUNT(E19,G19,I19,K19,M19,O19)) -> 0 | R19: =IF(T19="","",IF(T19=99999,"",T19)) -> 46309 | S19: =IF(T19="","",IF(T19=99999,"Concluído",IF(T19<TODAY(),"Atrasado",IF(T19=TODAY(),"Hoje","Em dia")))) -> Em dia | T19: =IF(COUNT(E19,G19,I19,K19,M19,O19)=0,"",MIN(IF(AND(E19<>"",F19=""),E19,99999),IF(AND(G19<>"",H19=""),G19,99999),IF(AND(I19<>"",J19=""),I19,99999),IF(AND(K19<>"",L19=""),K19,99999),IF(AND(M19<>"",N19=""),M19,99999),IF(AND(O19<>"",P19=""),O19,99999))) -> 46309
A20: 15 | B20: Doenças da Suprarrenal | C20: Clínica Médica | D20: 46311 | E20: =IF(OR(NOT(ISNUMBER($D20)),Config!$G$6<>"Sim"),"",$D20+Config!$F$6+IF(AND(Config!$F$6>0,WEEKDAY($D20+Config!$F$6)=Config!$E$24),1,0)) -> 46311 | G20: =IF(OR(NOT(ISNUMBER($D20)),Config!$G$7<>"Sim"),"",$D20+Config!$F$7+IF(AND(Config!$F$7>0,WEEKDAY($D20+Config!$F$7)=Config!$E$24),1,0)) -> 46312 | I20: =IF(OR(NOT(ISNUMBER($D20)),Config!$G$8<>"Sim"),"",$D20+Config!$F$8+IF(AND(Config!$F$8>0,WEEKDAY($D20+Config!$F$8)=Config!$E$24),1,0)) -> 46318 | K20: =IF(OR(NOT(ISNUMBER($D20)),Config!$G$9<>"Sim"),"",$D20+Config!$F$9+IF(AND(Config!$F$9>0,WEEKDAY($D20+Config!$F$9)=Config!$E$24),1,0)) -> 46326 | M20: =IF(OR(NOT(ISNUMBER($D20)),Config!$G$10<>"Sim"),"",$D20+Config!$F$10+IF(AND(Config!$F$10>0,WEEKDAY($D20+Config!$F$10)=Config!$E$24),1,0)) -> 46341 | O20: =IF(OR(NOT(ISNUMBER($D20)),Config!$G$11<>"Sim"),"",$D20+Config!$F$11+IF(AND(Config!$F$11>0,WEEKDAY($D20+Config!$F$11)=Config!$E$24),1,0)) -> 46371 | Q20: =IF(COUNT(E20,G20,I20,K20,M20,O20)=0,"",((E20<>"")*(F20<>"")+(G20<>"")*(H20<>"")+(I20<>"")*(J20<>"")+(K20<>"")*(L20<>"")+(M20<>"")*(N20<>"")+(O20<>"")*(P20<>""))/COUNT(E20,G20,I20,K20,M20,O20)) -> 0 | R20: =IF(T20="","",IF(T20=99999,"",T20)) -> 46311 | S20: =IF(T20="","",IF(T20=99999,"Concluído",IF(T20<TODAY(),"Atrasado",IF(T20=TODAY(),"Hoje","Em dia")))) -> Em dia | T20: =IF(COUNT(E20,G20,I20,K20,M20,O20)=0,"",MIN(IF(AND(E20<>"",F20=""),E20,99999),IF(AND(G20<>"",H20=""),G20,99999),IF(AND(I20<>"",J20=""),I20,99999),IF(AND(K20<>"",L20=""),K20,99999),IF(AND(M20<>"",N20=""),M20,99999),IF(AND(O20<>"",P20=""),O20,99999))) -> 46311
A21: 16 | B21: Infecções Sexualmente Transmissíveis | C21: Ginecologia e Obstetrícia | D21: 46311 | E21: =IF(OR(NOT(ISNUMBER($D21)),Config!$G$6<>"Sim"),"",$D21+Config!$F$6+IF(AND(Config!$F$6>0,WEEKDAY($D21+Config!$F$6)=Config!$E$24),1,0)) -> 46311 | G21: =IF(OR(NOT(ISNUMBER($D21)),Config!$G$7<>"Sim"),"",$D21+Config!$F$7+IF(AND(Config!$F$7>0,WEEKDAY($D21+Config!$F$7)=Config!$E$24),1,0)) -> 46312 | I21: =IF(OR(NOT(ISNUMBER($D21)),Config!$G$8<>"Sim"),"",$D21+Config!$F$8+IF(AND(Config!$F$8>0,WEEKDAY($D21+Config!$F$8)=Config!$E$24),1,0)) -> 46318 | K21: =IF(OR(NOT(ISNUMBER($D21)),Config!$G$9<>"Sim"),"",$D21+Config!$F$9+IF(AND(Config!$F$9>0,WEEKDAY($D21+Config!$F$9)=Config!$E$24),1,0)) -> 46326 | M21: =IF(OR(NOT(ISNUMBER($D21)),Config!$G$10<>"Sim"),"",$D21+Config!$F$10+IF(AND(Config!$F$10>0,WEEKDAY($D21+Config!$F$10)=Config!$E$24),1,0)) -> 46341 | O21: =IF(OR(NOT(ISNUMBER($D21)),Config!$G$11<>"Sim"),"",$D21+Config!$F$11+IF(AND(Config!$F$11>0,WEEKDAY($D21+Config!$F$11)=Config!$E$24),1,0)) -> 46371 | Q21: =IF(COUNT(E21,G21,I21,K21,M21,O21)=0,"",((E21<>"")*(F21<>"")+(G21<>"")*(H21<>"")+(I21<>"")*(J21<>"")+(K21<>"")*(L21<>"")+(M21<>"")*(N21<>"")+(O21<>"")*(P21<>""))/COUNT(E21,G21,I21,K21,M21,O21)) -> 0 | R21: =IF(T21="","",IF(T21=99999,"",T21)) -> 46311 | S21: =IF(T21="","",IF(T21=99999,"Concluído",IF(T21<TODAY(),"Atrasado",IF(T21=TODAY(),"Hoje","Em dia")))) -> Em dia | T21: =IF(COUNT(E21,G21,I21,K21,M21,O21)=0,"",MIN(IF(AND(E21<>"",F21=""),E21,99999),IF(AND(G21<>"",H21=""),G21,99999),IF(AND(I21<>"",J21=""),I21,99999),IF(AND(K21<>"",L21=""),K21,99999),IF(AND(M21<>"",N21=""),M21,99999),IF(AND(O21<>"",P21=""),O21,99999))) -> 46311
A22: 17 | B22: Parasitoses Intestinais | C22: Pediatria | D22: 46311 | E22: =IF(OR(NOT(ISNUMBER($D22)),Config!$G$6<>"Sim"),"",$D22+Config!$F$6+IF(AND(Config!$F$6>0,WEEKDAY($D22+Config!$F$6)=Config!$E$24),1,0)) -> 46311 | G22: =IF(OR(NOT(ISNUMBER($D22)),Config!$G$7<>"Sim"),"",$D22+Config!$F$7+IF(AND(Config!$F$7>0,WEEKDAY($D22+Config!$F$7)=Config!$E$24),1,0)) -> 46312 | I22: =IF(OR(NOT(ISNUMBER($D22)),Config!$G$8<>"Sim"),"",$D22+Config!$F$8+IF(AND(Config!$F$8>0,WEEKDAY($D22+Config!$F$8)=Config!$E$24),1,0)) -> 46318 | K22: =IF(OR(NOT(ISNUMBER($D22)),Config!$G$9<>"Sim"),"",$D22+Config!$F$9+IF(AND(Config!$F$9>0,WEEKDAY($D22+Config!$F$9)=Config!$E$24),1,0)) -> 46326 | M22: =IF(OR(NOT(ISNUMBER($D22)),Config!$G$10<>"Sim"),"",$D22+Config!$F$10+IF(AND(Config!$F$10>0,WEEKDAY($D22+Config!$F$10)=Config!$E$24),1,0)) -> 46341 | O22: =IF(OR(NOT(ISNUMBER($D22)),Config!$G$11<>"Sim"),"",$D22+Config!$F$11+IF(AND(Config!$F$11>0,WEEKDAY($D22+Config!$F$11)=Config!$E$24),1,0)) -> 46371 | Q22: =IF(COUNT(E22,G22,I22,K22,M22,O22)=0,"",((E22<>"")*(F22<>"")+(G22<>"")*(H22<>"")+(I22<>"")*(J22<>"")+(K22<>"")*(L22<>"")+(M22<>"")*(N22<>"")+(O22<>"")*(P22<>""))/COUNT(E22,G22,I22,K22,M22,O22)) -> 0 | R22: =IF(T22="","",IF(T22=99999,"",T22)) -> 46311 | S22: =IF(T22="","",IF(T22=99999,"Concluído",IF(T22<TODAY(),"Atrasado",IF(T22=TODAY(),"Hoje","Em dia")))) -> Em dia | T22: =IF(COUNT(E22,G22,I22,K22,M22,O22)=0,"",MIN(IF(AND(E22<>"",F22=""),E22,99999),IF(AND(G22<>"",H22=""),G22,99999),IF(AND(I22<>"",J22=""),I22,99999),IF(AND(K22<>"",L22=""),K22,99999),IF(AND(M22<>"",N22=""),M22,99999),IF(AND(O22<>"",P22=""),O22,99999))) -> 46311
A23: 18 | B23: HIV/AIDS | C23: Clínica Médica | D23: 46311 | E23: =IF(OR(NOT(ISNUMBER($D23)),Config!$G$6<>"Sim"),"",$D23+Config!$F$6+IF(AND(Config!$F$6>0,WEEKDAY($D23+Config!$F$6)=Config!$E$24),1,0)) -> 46311 | G23: =IF(OR(NOT(ISNUMBER($D23)),Config!$G$7<>"Sim"),"",$D23+Config!$F$7+IF(AND(Config!$F$7>0,WEEKDAY($D23+Config!$F$7)=Config!$E$24),1,0)) -> 46312 | I23: =IF(OR(NOT(ISNUMBER($D23)),Config!$G$8<>"Sim"),"",$D23+Config!$F$8+IF(AND(Config!$F$8>0,WEEKDAY($D23+Config!$F$8)=Config!$E$24),1,0)) -> 46318 | K23: =IF(OR(NOT(ISNUMBER($D23)),Config!$G$9<>"Sim"),"",$D23+Config!$F$9+IF(AND(Config!$F$9>0,WEEKDAY($D23+Config!$F$9)=Config!$E$24),1,0)) -> 46326 | M23: =IF(OR(NOT(ISNUMBER($D23)),Config!$G$10<>"Sim"),"",$D23+Config!$F$10+IF(AND(Config!$F$10>0,WEEKDAY($D23+Config!$F$10)=Config!$E$24),1,0)) -> 46341 | O23: =IF(OR(NOT(ISNUMBER($D23)),Config!$G$11<>"Sim"),"",$D23+Config!$F$11+IF(AND(Config!$F$11>0,WEEKDAY($D23+Config!$F$11)=Config!$E$24),1,0)) -> 46371 | Q23: =IF(COUNT(E23,G23,I23,K23,M23,O23)=0,"",((E23<>"")*(F23<>"")+(G23<>"")*(H23<>"")+(I23<>"")*(J23<>"")+(K23<>"")*(L23<>"")+(M23<>"")*(N23<>"")+(O23<>"")*(P23<>""))/COUNT(E23,G23,I23,K23,M23,O23)) -> 0 | R23: =IF(T23="","",IF(T23=99999,"",T23)) -> 46311 | S23: =IF(T23="","",IF(T23=99999,"Concluído",IF(T23<TODAY(),"Atrasado",IF(T23=TODAY(),"Hoje","Em dia")))) -> Em dia | T23: =IF(COUNT(E23,G23,I23,K23,M23,O23)=0,"",MIN(IF(AND(E23<>"",F23=""),E23,99999),IF(AND(G23<>"",H23=""),G23,99999),IF(AND(I23<>"",J23=""),I23,99999),IF(AND(K23<>"",L23=""),K23,99999),IF(AND(M23<>"",N23=""),M23,99999),IF(AND(O23<>"",P23=""),O23,99999))) -> 46311
A24: 19 | B24: Dermatologia I e II | C24: Clínica Médica | D24: 46314 | E24: =IF(OR(NOT(ISNUMBER($D24)),Config!$G$6<>"Sim"),"",$D24+Config!$F$6+IF(AND(Config!$F$6>0,WEEKDAY($D24+Config!$F$6)=Config!$E$24),1,0)) -> 46314 | G24: =IF(OR(NOT(ISNUMBER($D24)),Config!$G$7<>"Sim"),"",$D24+Config!$F$7+IF(AND(Config!$F$7>0,WEEKDAY($D24+Config!$F$7)=Config!$E$24),1,0)) -> 46315 | I24: =IF(OR(NOT(ISNUMBER($D24)),Config!$G$8<>"Sim"),"",$D24+Config!$F$8+IF(AND(Config!$F$8>0,WEEKDAY($D24+Config!$F$8)=Config!$E$24),1,0)) -> 46321 | K24: =IF(OR(NOT(ISNUMBER($D24)),Config!$G$9<>"Sim"),"",$D24+Config!$F$9+IF(AND(Config!$F$9>0,WEEKDAY($D24+Config!$F$9)=Config!$E$24),1,0)) -> 46329 | M24: =IF(OR(NOT(ISNUMBER($D24)),Config!$G$10<>"Sim"),"",$D24+Config!$F$10+IF(AND(Config!$F$10>0,WEEKDAY($D24+Config!$F$10)=Config!$E$24),1,0)) -> 46344 | O24: =IF(OR(NOT(ISNUMBER($D24)),Config!$G$11<>"Sim"),"",$D24+Config!$F$11+IF(AND(Config!$F$11>0,WEEKDAY($D24+Config!$F$11)=Config!$E$24),1,0)) -> 46374 | Q24: =IF(COUNT(E24,G24,I24,K24,M24,O24)=0,"",((E24<>"")*(F24<>"")+(G24<>"")*(H24<>"")+(I24<>"")*(J24<>"")+(K24<>"")*(L24<>"")+(M24<>"")*(N24<>"")+(O24<>"")*(P24<>""))/COUNT(E24,G24,I24,K24,M24,O24)) -> 0 | R24: =IF(T24="","",IF(T24=99999,"",T24)) -> 46314 | S24: =IF(T24="","",IF(T24=99999,"Concluído",IF(T24<TODAY(),"Atrasado",IF(T24=TODAY(),"Hoje","Em dia")))) -> Em dia | T24: =IF(COUNT(E24,G24,I24,K24,M24,O24)=0,"",MIN(IF(AND(E24<>"",F24=""),E24,99999),IF(AND(G24<>"",H24=""),G24,99999),IF(AND(I24<>"",J24=""),I24,99999),IF(AND(K24<>"",L24=""),K24,99999),IF(AND(M24<>"",N24=""),M24,99999),IF(AND(O24<>"",P24=""),O24,99999))) -> 46314
A25: 20 | B25: Bônus Oftalmo | C25: Cirurgia | D25: 46315 | E25: =IF(OR(NOT(ISNUMBER($D25)),Config!$G$6<>"Sim"),"",$D25+Config!$F$6+IF(AND(Config!$F$6>0,WEEKDAY($D25+Config!$F$6)=Config!$E$24),1,0)) -> 46315 | G25: =IF(OR(NOT(ISNUMBER($D25)),Config!$G$7<>"Sim"),"",$D25+Config!$F$7+IF(AND(Config!$F$7>0,WEEKDAY($D25+Config!$F$7)=Config!$E$24),1,0)) -> 46316 | I25: =IF(OR(NOT(ISNUMBER($D25)),Config!$G$8<>"Sim"),"",$D25+Config!$F$8+IF(AND(Config!$F$8>0,WEEKDAY($D25+Config!$F$8)=Config!$E$24),1,0)) -> 46322 | K25: =IF(OR(NOT(ISNUMBER($D25)),Config!$G$9<>"Sim"),"",$D25+Config!$F$9+IF(AND(Config!$F$9>0,WEEKDAY($D25+Config!$F$9)=Config!$E$24),1,0)) -> 46330 | M25: =IF(OR(NOT(ISNUMBER($D25)),Config!$G$10<>"Sim"),"",$D25+Config!$F$10+IF(AND(Config!$F$10>0,WEEKDAY($D25+Config!$F$10)=Config!$E$24),1,0)) -> 46345 | O25: =IF(OR(NOT(ISNUMBER($D25)),Config!$G$11<>"Sim"),"",$D25+Config!$F$11+IF(AND(Config!$F$11>0,WEEKDAY($D25+Config!$F$11)=Config!$E$24),1,0)) -> 46375 | Q25: =IF(COUNT(E25,G25,I25,K25,M25,O25)=0,"",((E25<>"")*(F25<>"")+(G25<>"")*(H25<>"")+(I25<>"")*(J25<>"")+(K25<>"")*(L25<>"")+(M25<>"")*(N25<>"")+(O25<>"")*(P25<>""))/COUNT(E25,G25,I25,K25,M25,O25)) -> 0 | R25: =IF(T25="","",IF(T25=99999,"",T25)) -> 46315 | S25: =IF(T25="","",IF(T25=99999,"Concluído",IF(T25<TODAY(),"Atrasado",IF(T25=TODAY(),"Hoje","Em dia")))) -> Em dia | T25: =IF(COUNT(E25,G25,I25,K25,M25,O25)=0,"",MIN(IF(AND(E25<>"",F25=""),E25,99999),IF(AND(G25<>"",H25=""),G25,99999),IF(AND(I25<>"",J25=""),I25,99999),IF(AND(K25<>"",L25=""),K25,99999),IF(AND(M25<>"",N25=""),M25,99999),IF(AND(O25<>"",P25=""),O25,99999))) -> 46315
A26: 21 | B26: Insuficiência Cardíaca | C26: Clínica Médica | D26: 46315 | E26: =IF(OR(NOT(ISNUMBER($D26)),Config!$G$6<>"Sim"),"",$D26+Config!$F$6+IF(AND(Config!$F$6>0,WEEKDAY($D26+Config!$F$6)=Config!$E$24),1,0)) -> 46315 | G26: =IF(OR(NOT(ISNUMBER($D26)),Config!$G$7<>"Sim"),"",$D26+Config!$F$7+IF(AND(Config!$F$7>0,WEEKDAY($D26+Config!$F$7)=Config!$E$24),1,0)) -> 46316 | I26: =IF(OR(NOT(ISNUMBER($D26)),Config!$G$8<>"Sim"),"",$D26+Config!$F$8+IF(AND(Config!$F$8>0,WEEKDAY($D26+Config!$F$8)=Config!$E$24),1,0)) -> 46322 | K26: =IF(OR(NOT(ISNUMBER($D26)),Config!$G$9<>"Sim"),"",$D26+Config!$F$9+IF(AND(Config!$F$9>0,WEEKDAY($D26+Config!$F$9)=Config!$E$24),1,0)) -> 46330 | M26: =IF(OR(NOT(ISNUMBER($D26)),Config!$G$10<>"Sim"),"",$D26+Config!$F$10+IF(AND(Config!$F$10>0,WEEKDAY($D26+Config!$F$10)=Config!$E$24),1,0)) -> 46345 | O26: =IF(OR(NOT(ISNUMBER($D26)),Config!$G$11<>"Sim"),"",$D26+Config!$F$11+IF(AND(Config!$F$11>0,WEEKDAY($D26+Config!$F$11)=Config!$E$24),1,0)) -> 46375 | Q26: =IF(COUNT(E26,G26,I26,K26,M26,O26)=0,"",((E26<>"")*(F26<>"")+(G26<>"")*(H26<>"")+(I26<>"")*(J26<>"")+(K26<>"")*(L26<>"")+(M26<>"")*(N26<>"")+(O26<>"")*(P26<>""))/COUNT(E26,G26,I26,K26,M26,O26)) -> 0 | R26: =IF(T26="","",IF(T26=99999,"",T26)) -> 46315 | S26: =IF(T26="","",IF(T26=99999,"Concluído",IF(T26<TODAY(),"Atrasado",IF(T26=TODAY(),"Hoje","Em dia")))) -> Em dia | T26: =IF(COUNT(E26,G26,I26,K26,M26,O26)=0,"",MIN(IF(AND(E26<>"",F26=""),E26,99999),IF(AND(G26<>"",H26=""),G26,99999),IF(AND(I26<>"",J26=""),I26,99999),IF(AND(K26<>"",L26=""),K26,99999),IF(AND(M26<>"",N26=""),M26,99999),IF(AND(O26<>"",P26=""),O26,99999))) -> 46315
... A31: 26 | B31: Fraqueza Muscular — Polineuropatias | C31: Clínica Médica | D31: 46322 | E31: =IF(OR(NOT(ISNUMBER($D31)),Config!$G$6<>"Sim"),"",$D31+Config!$F$6+IF(AND(Config!$F$6>0,WEEKDAY($D31+Config!$F$6)=Config!$E$24),1,0)) -> 46322 | G31: =IF(OR(NOT(ISNUMBER($D31)),Config!$G$7<>"Sim"),"",$D31+Config!$F$7+IF(AND(Config!$F$7>0,WEEKDAY($D31+Config!$F$7)=Config!$E$24),1,0)) -> 46323 | I31: =IF(OR(NOT(ISNUMBER($D31)),Config!$G$8<>"Sim"),"",$D31+Config!$F$8+IF(AND(Config!$F$8>0,WEEKDAY($D31+Config!$F$8)=Config!$E$24),1,0)) -> 46329 | K31: =IF(OR(NOT(ISNUMBER($D31)),Config!$G$9<>"Sim"),"",$D31+Config!$F$9+IF(AND(Config!$F$9>0,WEEKDAY($D31+Config!$F$9)=Config!$E$24),1,0)) -> 46337 | M31: =IF(OR(NOT(ISNUMBER($D31)),Config!$G$10<>"Sim"),"",$D31+Config!$F$10+IF(AND(Config!$F$10>0,WEEKDAY($D31+Config!$F$10)=Config!$E$24),1,0)) -> 46352 | O31: =IF(OR(NOT(ISNUMBER($D31)),Config!$G$11<>"Sim"),"",$D31+Config!$F$11+IF(AND(Config!$F$11>0,WEEKDAY($D31+Config!$F$11)=Config!$E$24),1,0)) -> 46382 | Q31: =IF(COUNT(E31,G31,I31,K31,M31,O31)=0,"",((E31<>"")*(F31<>"")+(G31<>"")*(H31<>"")+(I31<>"")*(J31<>"")+(K31<>"")*(L31<>"")+(M31<>"")*(N31<>"")+(O31<>"")*(P31<>""))/COUNT(E31,G31,I31,K31,M31,O31)) -> 0 | R31: =IF(T31="","",IF(T31=99999,"",T31)) -> 46322 | S31: =IF(T31="","",IF(T31=99999,"Concluído",IF(T31<TODAY(),"Atrasado",IF(T31=TODAY(),"Hoje","Em dia")))) -> Em dia | T31: =IF(COUNT(E31,G31,I31,K31,M31,O31)=0,"",MIN(IF(AND(E31<>"",F31=""),E31,99999),IF(AND(G31<>"",H31=""),G31,99999),IF(AND(I31<>"",J31=""),I31,99999),IF(AND(K31<>"",L31=""),K31,99999),IF(AND(M31<>"",N31=""),M31,99999),IF(AND(O31<>"",P31=""),O31,99999))) -> 46322
A32: 27 | E32: =IF(OR(NOT(ISNUMBER($D32)),Config!$G$6<>"Sim"),"",$D32+Config!$F$6+IF(AND(Config!$F$6>0,WEEKDAY($D32+Config!$F$6)=Config!$E$24),1,0)) | G32: =IF(OR(NOT(ISNUMBER($D32)),Config!$G$7<>"Sim"),"",$D32+Config!$F$7+IF(AND(Config!$F$7>0,WEEKDAY($D32+Config!$F$7)=Config!$E$24),1,0)) | I32: =IF(OR(NOT(ISNUMBER($D32)),Config!$G$8<>"Sim"),"",$D32+Config!$F$8+IF(AND(Config!$F$8>0,WEEKDAY($D32+Config!$F$8)=Config!$E$24),1,0)) | K32: =IF(OR(NOT(ISNUMBER($D32)),Config!$G$9<>"Sim"),"",$D32+Config!$F$9+IF(AND(Config!$F$9>0,WEEKDAY($D32+Config!$F$9)=Config!$E$24),1,0)) | M32: =IF(OR(NOT(ISNUMBER($D32)),Config!$G$10<>"Sim"),"",$D32+Config!$F$10+IF(AND(Config!$F$10>0,WEEKDAY($D32+Config!$F$10)=Config!$E$24),1,0)) | O32: =IF(OR(NOT(ISNUMBER($D32)),Config!$G$11<>"Sim"),"",$D32+Config!$F$11+IF(AND(Config!$F$11>0,WEEKDAY($D32+Config!$F$11)=Config!$E$24),1,0)) | Q32: =IF(COUNT(E32,G32,I32,K32,M32,O32)=0,"",((E32<>"")*(F32<>"")+(G32<>"")*(H32<>"")+(I32<>"")*(J32<>"")+(K32<>"")*(L32<>"")+(M32<>"")*(N32<>"")+(O32<>"")*(P32<>""))/COUNT(E32,G32,I32,K32,M32,O32)) | R32: =IF(T32="","",IF(T32=99999,"",T32)) | S32: =IF(T32="","",IF(T32=99999,"Concluído",IF(T32<TODAY(),"Atrasado",IF(T32=TODAY(),"Hoje","Em dia")))) | T32: =IF(COUNT(E32,G32,I32,K32,M32,O32)=0,"",MIN(IF(AND(E32<>"",F32=""),E32,99999),IF(AND(G32<>"",H32=""),G32,99999),IF(AND(I32<>"",J32=""),I32,99999),IF(AND(K32<>"",L32=""),K32,99999),IF(AND(M32<>"",N32=""),M32,99999),IF(AND(O32<>"",P32=""),O32,99999)))
A33: 28 | E33: =IF(OR(NOT(ISNUMBER($D33)),Config!$G$6<>"Sim"),"",$D33+Config!$F$6+IF(AND(Config!$F$6>0,WEEKDAY($D33+Config!$F$6)=Config!$E$24),1,0)) | G33: =IF(OR(NOT(ISNUMBER($D33)),Config!$G$7<>"Sim"),"",$D33+Config!$F$7+IF(AND(Config!$F$7>0,WEEKDAY($D33+Config!$F$7)=Config!$E$24),1,0)) | I33: =IF(OR(NOT(ISNUMBER($D33)),Config!$G$8<>"Sim"),"",$D33+Config!$F$8+IF(AND(Config!$F$8>0,WEEKDAY($D33+Config!$F$8)=Config!$E$24),1,0)) | K33: =IF(OR(NOT(ISNUMBER($D33)),Config!$G$9<>"Sim"),"",$D33+Config!$F$9+IF(AND(Config!$F$9>0,WEEKDAY($D33+Config!$F$9)=Config!$E$24),1,0)) | M33: =IF(OR(NOT(ISNUMBER($D33)),Config!$G$10<>"Sim"),"",$D33+Config!$F$10+IF(AND(Config!$F$10>0,WEEKDAY($D33+Config!$F$10)=Config!$E$24),1,0)) | O33: =IF(OR(NOT(ISNUMBER($D33)),Config!$G$11<>"Sim"),"",$D33+Config!$F$11+IF(AND(Config!$F$11>0,WEEKDAY($D33+Config!$F$11)=Config!$E$24),1,0)) | Q33: =IF(COUNT(E33,G33,I33,K33,M33,O33)=0,"",((E33<>"")*(F33<>"")+(G33<>"")*(H33<>"")+(I33<>"")*(J33<>"")+(K33<>"")*(L33<>"")+(M33<>"")*(N33<>"")+(O33<>"")*(P33<>""))/COUNT(E33,G33,I33,K33,M33,O33)) | R33: =IF(T33="","",IF(T33=99999,"",T33)) | S33: =IF(T33="","",IF(T33=99999,"Concluído",IF(T33<TODAY(),"Atrasado",IF(T33=TODAY(),"Hoje","Em dia")))) | T33: =IF(COUNT(E33,G33,I33,K33,M33,O33)=0,"",MIN(IF(AND(E33<>"",F33=""),E33,99999),IF(AND(G33<>"",H33=""),G33,99999),IF(AND(I33<>"",J33=""),I33,99999),IF(AND(K33<>"",L33=""),K33,99999),IF(AND(M33<>"",N33=""),M33,99999),IF(AND(O33<>"",P33=""),O33,99999)))
A34: 29 | E34: =IF(OR(NOT(ISNUMBER($D34)),Config!$G$6<>"Sim"),"",$D34+Config!$F$6+IF(AND(Config!$F$6>0,WEEKDAY($D34+Config!$F$6)=Config!$E$24),1,0)) | G34: =IF(OR(NOT(ISNUMBER($D34)),Config!$G$7<>"Sim"),"",$D34+Config!$F$7+IF(AND(Config!$F$7>0,WEEKDAY($D34+Config!$F$7)=Config!$E$24),1,0)) | I34: =IF(OR(NOT(ISNUMBER($D34)),Config!$G$8<>"Sim"),"",$D34+Config!$F$8+IF(AND(Config!$F$8>0,WEEKDAY($D34+Config!$F$8)=Config!$E$24),1,0)) | K34: =IF(OR(NOT(ISNUMBER($D34)),Config!$G$9<>"Sim"),"",$D34+Config!$F$9+IF(AND(Config!$F$9>0,WEEKDAY($D34+Config!$F$9)=Config!$E$24),1,0)) | M34: =IF(OR(NOT(ISNUMBER($D34)),Config!$G$10<>"Sim"),"",$D34+Config!$F$10+IF(AND(Config!$F$10>0,WEEKDAY($D34+Config!$F$10)=Config!$E$24),1,0)) | O34: =IF(OR(NOT(ISNUMBER($D34)),Config!$G$11<>"Sim"),"",$D34+Config!$F$11+IF(AND(Config!$F$11>0,WEEKDAY($D34+Config!$F$11)=Config!$E$24),1,0)) | Q34: =IF(COUNT(E34,G34,I34,K34,M34,O34)=0,"",((E34<>"")*(F34<>"")+(G34<>"")*(H34<>"")+(I34<>"")*(J34<>"")+(K34<>"")*(L34<>"")+(M34<>"")*(N34<>"")+(O34<>"")*(P34<>""))/COUNT(E34,G34,I34,K34,M34,O34)) | R34: =IF(T34="","",IF(T34=99999,"",T34)) | S34: =IF(T34="","",IF(T34=99999,"Concluído",IF(T34<TODAY(),"Atrasado",IF(T34=TODAY(),"Hoje","Em dia")))) | T34: =IF(COUNT(E34,G34,I34,K34,M34,O34)=0,"",MIN(IF(AND(E34<>"",F34=""),E34,99999),IF(AND(G34<>"",H34=""),G34,99999),IF(AND(I34<>"",J34=""),I34,99999),IF(AND(K34<>"",L34=""),K34,99999),IF(AND(M34<>"",N34=""),M34,99999),IF(AND(O34<>"",P34=""),O34,99999)))
A35: 30 | E35: =IF(OR(NOT(ISNUMBER($D35)),Config!$G$6<>"Sim"),"",$D35+Config!$F$6+IF(AND(Config!$F$6>0,WEEKDAY($D35+Config!$F$6)=Config!$E$24),1,0)) | G35: =IF(OR(NOT(ISNUMBER($D35)),Config!$G$7<>"Sim"),"",$D35+Config!$F$7+IF(AND(Config!$F$7>0,WEEKDAY($D35+Config!$F$7)=Config!$E$24),1,0)) | I35: =IF(OR(NOT(ISNUMBER($D35)),Config!$G$8<>"Sim"),"",$D35+Config!$F$8+IF(AND(Config!$F$8>0,WEEKDAY($D35+Config!$F$8)=Config!$E$24),1,0)) | K35: =IF(OR(NOT(ISNUMBER($D35)),Config!$G$9<>"Sim"),"",$D35+Config!$F$9+IF(AND(Config!$F$9>0,WEEKDAY($D35+Config!$F$9)=Config!$E$24),1,0)) | M35: =IF(OR(NOT(ISNUMBER($D35)),Config!$G$10<>"Sim"),"",$D35+Config!$F$10+IF(AND(Config!$F$10>0,WEEKDAY($D35+Config!$F$10)=Config!$E$24),1,0)) | O35: =IF(OR(NOT(ISNUMBER($D35)),Config!$G$11<>"Sim"),"",$D35+Config!$F$11+IF(AND(Config!$F$11>0,WEEKDAY($D35+Config!$F$11)=Config!$E$24),1,0)) | Q35: =IF(COUNT(E35,G35,I35,K35,M35,O35)=0,"",((E35<>"")*(F35<>"")+(G35<>"")*(H35<>"")+(I35<>"")*(J35<>"")+(K35<>"")*(L35<>"")+(M35<>"")*(N35<>"")+(O35<>"")*(P35<>""))/COUNT(E35,G35,I35,K35,M35,O35)) | R35: =IF(T35="","",IF(T35=99999,"",T35)) | S35: =IF(T35="","",IF(T35=99999,"Concluído",IF(T35<TODAY(),"Atrasado",IF(T35=TODAY(),"Hoje","Em dia")))) | T35: =IF(COUNT(E35,G35,I35,K35,M35,O35)=0,"",MIN(IF(AND(E35<>"",F35=""),E35,99999),IF(AND(G35<>"",H35=""),G35,99999),IF(AND(I35<>"",J35=""),I35,99999),IF(AND(K35<>"",L35=""),K35,99999),IF(AND(M35<>"",N35=""),M35,99999),IF(AND(O35<>"",P35=""),O35,99999)))
A36: 31 | E36: =IF(OR(NOT(ISNUMBER($D36)),Config!$G$6<>"Sim"),"",$D36+Config!$F$6+IF(AND(Config!$F$6>0,WEEKDAY($D36+Config!$F$6)=Config!$E$24),1,0)) | G36: =IF(OR(NOT(ISNUMBER($D36)),Config!$G$7<>"Sim"),"",$D36+Config!$F$7+IF(AND(Config!$F$7>0,WEEKDAY($D36+Config!$F$7)=Config!$E$24),1,0)) | I36: =IF(OR(NOT(ISNUMBER($D36)),Config!$G$8<>"Sim"),"",$D36+Config!$F$8+IF(AND(Config!$F$8>0,WEEKDAY($D36+Config!$F$8)=Config!$E$24),1,0)) | K36: =IF(OR(NOT(ISNUMBER($D36)),Config!$G$9<>"Sim"),"",$D36+Config!$F$9+IF(AND(Config!$F$9>0,WEEKDAY($D36+Config!$F$9)=Config!$E$24),1,0)) | M36: =IF(OR(NOT(ISNUMBER($D36)),Config!$G$10<>"Sim"),"",$D36+Config!$F$10+IF(AND(Config!$F$10>0,WEEKDAY($D36+Config!$F$10)=Config!$E$24),1,0)) | O36: =IF(OR(NOT(ISNUMBER($D36)),Config!$G$11<>"Sim"),"",$D36+Config!$F$11+IF(AND(Config!$F$11>0,WEEKDAY($D36+Config!$F$11)=Config!$E$24),1,0)) | Q36: =IF(COUNT(E36,G36,I36,K36,M36,O36)=0,"",((E36<>"")*(F36<>"")+(G36<>"")*(H36<>"")+(I36<>"")*(J36<>"")+(K36<>"")*(L36<>"")+(M36<>"")*(N36<>"")+(O36<>"")*(P36<>""))/COUNT(E36,G36,I36,K36,M36,O36)) | R36: =IF(T36="","",IF(T36=99999,"",T36)) | S36: =IF(T36="","",IF(T36=99999,"Concluído",IF(T36<TODAY(),"Atrasado",IF(T36=TODAY(),"Hoje","Em dia")))) | T36: =IF(COUNT(E36,G36,I36,K36,M36,O36)=0,"",MIN(IF(AND(E36<>"",F36=""),E36,99999),IF(AND(G36<>"",H36=""),G36,99999),IF(AND(I36<>"",J36=""),I36,99999),IF(AND(K36<>"",L36=""),K36,99999),IF(AND(M36<>"",N36=""),M36,99999),IF(AND(O36<>"",P36=""),O36,99999)))
A37: 32 | E37: =IF(OR(NOT(ISNUMBER($D37)),Config!$G$6<>"Sim"),"",$D37+Config!$F$6+IF(AND(Config!$F$6>0,WEEKDAY($D37+Config!$F$6)=Config!$E$24),1,0)) | G37: =IF(OR(NOT(ISNUMBER($D37)),Config!$G$7<>"Sim"),"",$D37+Config!$F$7+IF(AND(Config!$F$7>0,WEEKDAY($D37+Config!$F$7)=Config!$E$24),1,0)) | I37: =IF(OR(NOT(ISNUMBER($D37)),Config!$G$8<>"Sim"),"",$D37+Config!$F$8+IF(AND(Config!$F$8>0,WEEKDAY($D37+Config!$F$8)=Config!$E$24),1,0)) | K37: =IF(OR(NOT(ISNUMBER($D37)),Config!$G$9<>"Sim"),"",$D37+Config!$F$9+IF(AND(Config!$F$9>0,WEEKDAY($D37+Config!$F$9)=Config!$E$24),1,0)) | M37: =IF(OR(NOT(ISNUMBER($D37)),Config!$G$10<>"Sim"),"",$D37+Config!$F$10+IF(AND(Config!$F$10>0,WEEKDAY($D37+Config!$F$10)=Config!$E$24),1,0)) | O37: =IF(OR(NOT(ISNUMBER($D37)),Config!$G$11<>"Sim"),"",$D37+Config!$F$11+IF(AND(Config!$F$11>0,WEEKDAY($D37+Config!$F$11)=Config!$E$24),1,0)) | Q37: =IF(COUNT(E37,G37,I37,K37,M37,O37)=0,"",((E37<>"")*(F37<>"")+(G37<>"")*(H37<>"")+(I37<>"")*(J37<>"")+(K37<>"")*(L37<>"")+(M37<>"")*(N37<>"")+(O37<>"")*(P37<>""))/COUNT(E37,G37,I37,K37,M37,O37)) | R37: =IF(T37="","",IF(T37=99999,"",T37)) | S37: =IF(T37="","",IF(T37=99999,"Concluído",IF(T37<TODAY(),"Atrasado",IF(T37=TODAY(),"Hoje","Em dia")))) | T37: =IF(COUNT(E37,G37,I37,K37,M37,O37)=0,"",MIN(IF(AND(E37<>"",F37=""),E37,99999),IF(AND(G37<>"",H37=""),G37,99999),IF(AND(I37<>"",J37=""),I37,99999),IF(AND(K37<>"",L37=""),K37,99999),IF(AND(M37<>"",N37=""),M37,99999),IF(AND(O37<>"",P37=""),O37,99999)))
A38: 33 | E38: =IF(OR(NOT(ISNUMBER($D38)),Config!$G$6<>"Sim"),"",$D38+Config!$F$6+IF(AND(Config!$F$6>0,WEEKDAY($D38+Config!$F$6)=Config!$E$24),1,0)) | G38: =IF(OR(NOT(ISNUMBER($D38)),Config!$G$7<>"Sim"),"",$D38+Config!$F$7+IF(AND(Config!$F$7>0,WEEKDAY($D38+Config!$F$7)=Config!$E$24),1,0)) | I38: =IF(OR(NOT(ISNUMBER($D38)),Config!$G$8<>"Sim"),"",$D38+Config!$F$8+IF(AND(Config!$F$8>0,WEEKDAY($D38+Config!$F$8)=Config!$E$24),1,0)) | K38: =IF(OR(NOT(ISNUMBER($D38)),Config!$G$9<>"Sim"),"",$D38+Config!$F$9+IF(AND(Config!$F$9>0,WEEKDAY($D38+Config!$F$9)=Config!$E$24),1,0)) | M38: =IF(OR(NOT(ISNUMBER($D38)),Config!$G$10<>"Sim"),"",$D38+Config!$F$10+IF(AND(Config!$F$10>0,WEEKDAY($D38+Config!$F$10)=Config!$E$24),1,0)) | O38: =IF(OR(NOT(ISNUMBER($D38)),Config!$G$11<>"Sim"),"",$D38+Config!$F$11+IF(AND(Config!$F$11>0,WEEKDAY($D38+Config!$F$11)=Config!$E$24),1,0)) | Q38: =IF(COUNT(E38,G38,I38,K38,M38,O38)=0,"",((E38<>"")*(F38<>"")+(G38<>"")*(H38<>"")+(I38<>"")*(J38<>"")+(K38<>"")*(L38<>"")+(M38<>"")*(N38<>"")+(O38<>"")*(P38<>""))/COUNT(E38,G38,I38,K38,M38,O38)) | R38: =IF(T38="","",IF(T38=99999,"",T38)) | S38: =IF(T38="","",IF(T38=99999,"Concluído",IF(T38<TODAY(),"Atrasado",IF(T38=TODAY(),"Hoje","Em dia")))) | T38: =IF(COUNT(E38,G38,I38,K38,M38,O38)=0,"",MIN(IF(AND(E38<>"",F38=""),E38,99999),IF(AND(G38<>"",H38=""),G38,99999),IF(AND(I38<>"",J38=""),I38,99999),IF(AND(K38<>"",L38=""),K38,99999),IF(AND(M38<>"",N38=""),M38,99999),IF(AND(O38<>"",P38=""),O38,99999)))
A39: 34 | E39: =IF(OR(NOT(ISNUMBER($D39)),Config!$G$6<>"Sim"),"",$D39+Config!$F$6+IF(AND(Config!$F$6>0,WEEKDAY($D39+Config!$F$6)=Config!$E$24),1,0)) | G39: =IF(OR(NOT(ISNUMBER($D39)),Config!$G$7<>"Sim"),"",$D39+Config!$F$7+IF(AND(Config!$F$7>0,WEEKDAY($D39+Config!$F$7)=Config!$E$24),1,0)) | I39: =IF(OR(NOT(ISNUMBER($D39)),Config!$G$8<>"Sim"),"",$D39+Config!$F$8+IF(AND(Config!$F$8>0,WEEKDAY($D39+Config!$F$8)=Config!$E$24),1,0)) | K39: =IF(OR(NOT(ISNUMBER($D39)),Config!$G$9<>"Sim"),"",$D39+Config!$F$9+IF(AND(Config!$F$9>0,WEEKDAY($D39+Config!$F$9)=Config!$E$24),1,0)) | M39: =IF(OR(NOT(ISNUMBER($D39)),Config!$G$10<>"Sim"),"",$D39+Config!$F$10+IF(AND(Config!$F$10>0,WEEKDAY($D39+Config!$F$10)=Config!$E$24),1,0)) | O39: =IF(OR(NOT(ISNUMBER($D39)),Config!$G$11<>"Sim"),"",$D39+Config!$F$11+IF(AND(Config!$F$11>0,WEEKDAY($D39+Config!$F$11)=Config!$E$24),1,0)) | Q39: =IF(COUNT(E39,G39,I39,K39,M39,O39)=0,"",((E39<>"")*(F39<>"")+(G39<>"")*(H39<>"")+(I39<>"")*(J39<>"")+(K39<>"")*(L39<>"")+(M39<>"")*(N39<>"")+(O39<>"")*(P39<>""))/COUNT(E39,G39,I39,K39,M39,O39)) | R39: =IF(T39="","",IF(T39=99999,"",T39)) | S39: =IF(T39="","",IF(T39=99999,"Concluído",IF(T39<TODAY(),"Atrasado",IF(T39=TODAY(),"Hoje","Em dia")))) | T39: =IF(COUNT(E39,G39,I39,K39,M39,O39)=0,"",MIN(IF(AND(E39<>"",F39=""),E39,99999),IF(AND(G39<>"",H39=""),G39,99999),IF(AND(I39<>"",J39=""),I39,99999),IF(AND(K39<>"",L39=""),K39,99999),IF(AND(M39<>"",N39=""),M39,99999),IF(AND(O39<>"",P39=""),O39,99999)))
A40: 35 | E40: =IF(OR(NOT(ISNUMBER($D40)),Config!$G$6<>"Sim"),"",$D40+Config!$F$6+IF(AND(Config!$F$6>0,WEEKDAY($D40+Config!$F$6)=Config!$E$24),1,0)) | G40: =IF(OR(NOT(ISNUMBER($D40)),Config!$G$7<>"Sim"),"",$D40+Config!$F$7+IF(AND(Config!$F$7>0,WEEKDAY($D40+Config!$F$7)=Config!$E$24),1,0)) | I40: =IF(OR(NOT(ISNUMBER($D40)),Config!$G$8<>"Sim"),"",$D40+Config!$F$8+IF(AND(Config!$F$8>0,WEEKDAY($D40+Config!$F$8)=Config!$E$24),1,0)) | K40: =IF(OR(NOT(ISNUMBER($D40)),Config!$G$9<>"Sim"),"",$D40+Config!$F$9+IF(AND(Config!$F$9>0,WEEKDAY($D40+Config!$F$9)=Config!$E$24),1,0)) | M40: =IF(OR(NOT(ISNUMBER($D40)),Config!$G$10<>"Sim"),"",$D40+Config!$F$10+IF(AND(Config!$F$10>0,WEEKDAY($D40+Config!$F$10)=Config!$E$24),1,0)) | O40: =IF(OR(NOT(ISNUMBER($D40)),Config!$G$11<>"Sim"),"",$D40+Config!$F$11+IF(AND(Config!$F$11>0,WEEKDAY($D40+Config!$F$11)=Config!$E$24),1,0)) | Q40: =IF(COUNT(E40,G40,I40,K40,M40,O40)=0,"",((E40<>"")*(F40<>"")+(G40<>"")*(H40<>"")+(I40<>"")*(J40<>"")+(K40<>"")*(L40<>"")+(M40<>"")*(N40<>"")+(O40<>"")*(P40<>""))/COUNT(E40,G40,I40,K40,M40,O40)) | R40: =IF(T40="","",IF(T40=99999,"",T40)) | S40: =IF(T40="","",IF(T40=99999,"Concluído",IF(T40<TODAY(),"Atrasado",IF(T40=TODAY(),"Hoje","Em dia")))) | T40: =IF(COUNT(E40,G40,I40,K40,M40,O40)=0,"",MIN(IF(AND(E40<>"",F40=""),E40,99999),IF(AND(G40<>"",H40=""),G40,99999),IF(AND(I40<>"",J40=""),I40,99999),IF(AND(K40<>"",L40=""),K40,99999),IF(AND(M40<>"",N40=""),M40,99999),IF(AND(O40<>"",P40=""),O40,99999)))
A41: 36 | E41: =IF(OR(NOT(ISNUMBER($D41)),Config!$G$6<>"Sim"),"",$D41+Config!$F$6+IF(AND(Config!$F$6>0,WEEKDAY($D41+Config!$F$6)=Config!$E$24),1,0)) | G41: =IF(OR(NOT(ISNUMBER($D41)),Config!$G$7<>"Sim"),"",$D41+Config!$F$7+IF(AND(Config!$F$7>0,WEEKDAY($D41+Config!$F$7)=Config!$E$24),1,0)) | I41: =IF(OR(NOT(ISNUMBER($D41)),Config!$G$8<>"Sim"),"",$D41+Config!$F$8+IF(AND(Config!$F$8>0,WEEKDAY($D41+Config!$F$8)=Config!$E$24),1,0)) | K41: =IF(OR(NOT(ISNUMBER($D41)),Config!$G$9<>"Sim"),"",$D41+Config!$F$9+IF(AND(Config!$F$9>0,WEEKDAY($D41+Config!$F$9)=Config!$E$24),1,0)) | M41: =IF(OR(NOT(ISNUMBER($D41)),Config!$G$10<>"Sim"),"",$D41+Config!$F$10+IF(AND(Config!$F$10>0,WEEKDAY($D41+Config!$F$10)=Config!$E$24),1,0)) | O41: =IF(OR(NOT(ISNUMBER($D41)),Config!$G$11<>"Sim"),"",$D41+Config!$F$11+IF(AND(Config!$F$11>0,WEEKDAY($D41+Config!$F$11)=Config!$E$24),1,0)) | Q41: =IF(COUNT(E41,G41,I41,K41,M41,O41)=0,"",((E41<>"")*(F41<>"")+(G41<>"")*(H41<>"")+(I41<>"")*(J41<>"")+(K41<>"")*(L41<>"")+(M41<>"")*(N41<>"")+(O41<>"")*(P41<>""))/COUNT(E41,G41,I41,K41,M41,O41)) | R41: =IF(T41="","",IF(T41=99999,"",T41)) | S41: =IF(T41="","",IF(T41=99999,"Concluído",IF(T41<TODAY(),"Atrasado",IF(T41=TODAY(),"Hoje","Em dia")))) | T41: =IF(COUNT(E41,G41,I41,K41,M41,O41)=0,"",MIN(IF(AND(E41<>"",F41=""),E41,99999),IF(AND(G41<>"",H41=""),G41,99999),IF(AND(I41<>"",J41=""),I41,99999),IF(AND(K41<>"",L41=""),K41,99999),IF(AND(M41<>"",N41=""),M41,99999),IF(AND(O41<>"",P41=""),O41,99999)))
A42: 37 | E42: =IF(OR(NOT(ISNUMBER($D42)),Config!$G$6<>"Sim"),"",$D42+Config!$F$6+IF(AND(Config!$F$6>0,WEEKDAY($D42+Config!$F$6)=Config!$E$24),1,0)) | G42: =IF(OR(NOT(ISNUMBER($D42)),Config!$G$7<>"Sim"),"",$D42+Config!$F$7+IF(AND(Config!$F$7>0,WEEKDAY($D42+Config!$F$7)=Config!$E$24),1,0)) | I42: =IF(OR(NOT(ISNUMBER($D42)),Config!$G$8<>"Sim"),"",$D42+Config!$F$8+IF(AND(Config!$F$8>0,WEEKDAY($D42+Config!$F$8)=Config!$E$24),1,0)) | K42: =IF(OR(NOT(ISNUMBER($D42)),Config!$G$9<>"Sim"),"",$D42+Config!$F$9+IF(AND(Config!$F$9>0,WEEKDAY($D42+Config!$F$9)=Config!$E$24),1,0)) | M42: =IF(OR(NOT(ISNUMBER($D42)),Config!$G$10<>"Sim"),"",$D42+Config!$F$10+IF(AND(Config!$F$10>0,WEEKDAY($D42+Config!$F$10)=Config!$E$24),1,0)) | O42: =IF(OR(NOT(ISNUMBER($D42)),Config!$G$11<>"Sim"),"",$D42+Config!$F$11+IF(AND(Config!$F$11>0,WEEKDAY($D42+Config!$F$11)=Config!$E$24),1,0)) | Q42: =IF(COUNT(E42,G42,I42,K42,M42,O42)=0,"",((E42<>"")*(F42<>"")+(G42<>"")*(H42<>"")+(I42<>"")*(J42<>"")+(K42<>"")*(L42<>"")+(M42<>"")*(N42<>"")+(O42<>"")*(P42<>""))/COUNT(E42,G42,I42,K42,M42,O42)) | R42: =IF(T42="","",IF(T42=99999,"",T42)) | S42: =IF(T42="","",IF(T42=99999,"Concluído",IF(T42<TODAY(),"Atrasado",IF(T42=TODAY(),"Hoje","Em dia")))) | T42: =IF(COUNT(E42,G42,I42,K42,M42,O42)=0,"",MIN(IF(AND(E42<>"",F42=""),E42,99999),IF(AND(G42<>"",H42=""),G42,99999),IF(AND(I42<>"",J42=""),I42,99999),IF(AND(K42<>"",L42=""),K42,99999),IF(AND(M42<>"",N42=""),M42,99999),IF(AND(O42<>"",P42=""),O42,99999)))
A43: 38 | E43: =IF(OR(NOT(ISNUMBER($D43)),Config!$G$6<>"Sim"),"",$D43+Config!$F$6+IF(AND(Config!$F$6>0,WEEKDAY($D43+Config!$F$6)=Config!$E$24),1,0)) | G43: =IF(OR(NOT(ISNUMBER($D43)),Config!$G$7<>"Sim"),"",$D43+Config!$F$7+IF(AND(Config!$F$7>0,WEEKDAY($D43+Config!$F$7)=Config!$E$24),1,0)) | I43: =IF(OR(NOT(ISNUMBER($D43)),Config!$G$8<>"Sim"),"",$D43+Config!$F$8+IF(AND(Config!$F$8>0,WEEKDAY($D43+Config!$F$8)=Config!$E$24),1,0)) | K43: =IF(OR(NOT(ISNUMBER($D43)),Config!$G$9<>"Sim"),"",$D43+Config!$F$9+IF(AND(Config!$F$9>0,WEEKDAY($D43+Config!$F$9)=Config!$E$24),1,0)) | M43: =IF(OR(NOT(ISNUMBER($D43)),Config!$G$10<>"Sim"),"",$D43+Config!$F$10+IF(AND(Config!$F$10>0,WEEKDAY($D43+Config!$F$10)=Config!$E$24),1,0)) | O43: =IF(OR(NOT(ISNUMBER($D43)),Config!$G$11<>"Sim"),"",$D43+Config!$F$11+IF(AND(Config!$F$11>0,WEEKDAY($D43+Config!$F$11)=Config!$E$24),1,0)) | Q43: =IF(COUNT(E43,G43,I43,K43,M43,O43)=0,"",((E43<>"")*(F43<>"")+(G43<>"")*(H43<>"")+(I43<>"")*(J43<>"")+(K43<>"")*(L43<>"")+(M43<>"")*(N43<>"")+(O43<>"")*(P43<>""))/COUNT(E43,G43,I43,K43,M43,O43)) | R43: =IF(T43="","",IF(T43=99999,"",T43)) | S43: =IF(T43="","",IF(T43=99999,"Concluído",IF(T43<TODAY(),"Atrasado",IF(T43=TODAY(),"Hoje","Em dia")))) | T43: =IF(COUNT(E43,G43,I43,K43,M43,O43)=0,"",MIN(IF(AND(E43<>"",F43=""),E43,99999),IF(AND(G43<>"",H43=""),G43,99999),IF(AND(I43<>"",J43=""),I43,99999),IF(AND(K43<>"",L43=""),K43,99999),IF(AND(M43<>"",N43=""),M43,99999),IF(AND(O43<>"",P43=""),O43,99999)))
... A305: 300 | E305: =IF(OR(NOT(ISNUMBER($D305)),Config!$G$6<>"Sim"),"",$D305+Config!$F$6+IF(AND(Config!$F$6>0,WEEKDAY($D305+Config!$F$6)=Config!$E$24),1,0)) | G305: =IF(OR(NOT(ISNUMBER($D305)),Config!$G$7<>"Sim"),"",$D305+Config!$F$7+IF(AND(Config!$F$7>0,WEEKDAY($D305+Config!$F$7)=Config!$E$24),1,0)) | I305: =IF(OR(NOT(ISNUMBER($D305)),Config!$G$8<>"Sim"),"",$D305+Config!$F$8+IF(AND(Config!$F$8>0,WEEKDAY($D305+Config!$F$8)=Config!$E$24),1,0)) | K305: =IF(OR(NOT(ISNUMBER($D305)),Config!$G$9<>"Sim"),"",$D305+Config!$F$9+IF(AND(Config!$F$9>0,WEEKDAY($D305+Config!$F$9)=Config!$E$24),1,0)) | M305: =IF(OR(NOT(ISNUMBER($D305)),Config!$G$10<>"Sim"),"",$D305+Config!$F$10+IF(AND(Config!$F$10>0,WEEKDAY($D305+Config!$F$10)=Config!$E$24),1,0)) | O305: =IF(OR(NOT(ISNUMBER($D305)),Config!$G$11<>"Sim"),"",$D305+Config!$F$11+IF(AND(Config!$F$11>0,WEEKDAY($D305+Config!$F$11)=Config!$E$24),1,0)) | Q305: =IF(COUNT(E305,G305,I305,K305,M305,O305)=0,"",((E305<>"")*(F305<>"")+(G305<>"")*(H305<>"")+(I305<>"")*(J305<>"")+(K305<>"")*(L305<>"")+(M305<>"")*(N305<>"")+(O305<>"")*(P305<>""))/COUNT(E305,G305,I305,K305,M305,O305)) | R305: =IF(T305="","",IF(T305=99999,"",T305)) | S305: =IF(T305="","",IF(T305=99999,"Concluído",IF(T305<TODAY(),"Atrasado",IF(T305=TODAY(),"Hoje","Em dia")))) | T305: =IF(COUNT(E305,G305,I305,K305,M305,O305)=0,"",MIN(IF(AND(E305<>"",F305=""),E305,99999),IF(AND(G305<>"",H305=""),G305,99999),IF(AND(I305<>"",J305=""),I305,99999),IF(AND(K305<>"",L305=""),K305,99999),IF(AND(M305<>"",N305=""),M305,99999),IF(AND(O305<>"",P305=""),O305,99999)))

Sheet Avulsos
A1: Avulsos — simulados, questões e compromissos
A2: Eventos com data fixa que não seguem as revisões automáticas (ex.: simulado UFCSPA, bloco de 100 questões, plantão).
A3: A categoria define a cor no calendário. Marque ✓ (ou x) em Feito quando concluir.
A5: Nº | B5: Data | C5: Título / descrição | D5: Categoria | E5: Grande Área (opcional) | F5: Feito | G5: Observações
A6: 1 | B6: 46301 | C6: UFCSPA 2026 | D6: Simulado | F6: ✓ | G6: Prova na íntegra
A7: 2
A8: 3
A9: 4
A10: 5
A11: 6
A12: 7
A13: 8
A14: 9
A15: 10
A16: 11
A17: 12
A18: 13
... A205: 200

Sheet Calendário
B1: AGENDADOR DE REVISÕES | F1: Mês | H1: Semana | J1: Tabela | L1: Painel | N1: + Novo tema
